Workbook

Sheet Fコード表
A1: SEQ | B1: JFAGY code | C1: Allergen Term（JP） | D1: Furigana（JP） | E1: Allergen Term（EN） | F1: Level | G1: Ascii Tree（JP） | H1: Ascii Tree（EN） | I1: Main 100 | J1: Clinical Guideline | K1: CXGCATEGORY | L1: RECORDDATE | M1: ENDDATE
A2: 1 | B2: 00F | C2: 食品 | D2: しょくひん | E2: Food | F2: 1 | G2: 食品 | H2: Food | I2: 1 | J2: 1 | K2: 0 | L2: 00000000 | M2: 99999999
A3: 2 | B3: J9FA00000000 | C3: 農産食品 | D3: のうさんしょくひん | E3: Agricultural food | F3: 2 | G3: ├ 農産食品 | H3: ├ Agricultural food | I3: 1 | K3: 0 | L3: 00000000 | M3: 99999999
A4: 3 | B4: J9FA11000000 | C4: もみ | D4: もみ | E4: Paddy rice | F4: 3 | G4: │ ├ もみ | H4: │ ├ Paddy rice | K4: 0 | L4: 00000000 | M4: 99999999
A5: 4 | B5: J9FA12000000 | C5: 玄米 | D5: げんまい | E5: Brown rice | F5: 3 | G5: │ ├ 玄米 | H5: │ ├ Brown rice | I5: 1 | K5: 0 | L5: 00000000 | M5: 99999999
A6: 5 | B6: J9FA12000011 | C6: 米ぬか | D6: こめぬか | E6: Rice bran | F6: 6 | G6: │ │ └ 米ぬか | H6: │ │ └ Rice bran | J6: 1 | K6: 0 | L6: 00000000 | M6: 99999999
A7: 6 | B7: J9FA13000000 | C7: 白米 | D7: はくまい | E7: White rice | F7: 3 | G7: │ ├ 白米 | H7: │ ├ White rice | I7: 1 | K7: 0 | L7: 00000000 | M7: 99999999
A8: 7 | B8: J9FA13000011 | C8: もち | D8: もち | E8: Glutinous rice | F8: 6 | G8: │ │ ├ もち | H8: │ │ ├ Glutinous rice | K8: 0 | L8: 00000000 | M8: 99999999
A9: 8 | B9: J9FA13000012 | C9: 米粉 | D9: こめこ | E9: Rice flour | F9: 6 | G9: │ │ └ 米粉 | H9: │ │ └ Rice flour | K9: 0 | L9: 00000000 | M9: 99999999
A10: 9 | B10: J9FA14000000 | C10: 大麦 | D10: おおむぎ | E10: Barley | F10: 3 | G10: │ ├ 大麦 | H10: │ ├ Barley | I10: 1 | K10: 0 | L10: 00000000 | M10: 99999999
A11: 10 | B11: J9FA14000011 | C11: 大麦粉 | D11: おおむぎこ | E11: Barley flour | F11: 6 | G11: │ │ ├ 大麦粉 | H11: │ │ ├ Barley flour | J11: 1 | K11: 0 | L11: 00000000 | M11: 99999999
A12: 11 | B12: J9FA14000012 | C12: 麦茶 | D12: むぎちゃ | E12: Barley tea | F12: 6 | G12: │ │ └ 麦茶 | H12: │ │ └ Barley tea | K12: 0 | L12: 00000000 | M12: 99999999
A13: 12 | B13: J9FA15000000 | C13: 小麦 | D13: こむぎ | E13: Wheat | F13: 3 | G13: │ ├ 小麦 | H13: │ ├ Wheat | I13: 1 | J13: 1 | K13: 0 | L13: 00000000 | M13: 99999999
A14: 13 | B14: J9FA15000011 | C14: 小麦ふすま | D14: こむぎふすま | E14: Wheat bran | F14: 6 | G14: │ │ ├ 小麦ふすま | H14: │ │ ├ Wheat bran | K14: 0 | L14: 00000000 | M14: 99999999
A15: 14 | B15: J9FA15000012 | C15: こむぎ胚芽 | D15: こむぎはいが | E15: Wheat germ | F15: 6 | G15: │ │ ├ こむぎ胚芽 | H15: │ │ ├ Wheat germ | J15: 1 | K15: 0 | L15: 00000000 | M15: 99999999
A16: 15 | B16: J9FA15000013 | C16: グルテン | D16: ぐるてん | E16: Gluten | F16: 6 | G16: │ │ ├ グルテン | H16: │ │ ├ Gluten | J16: 1 | K16: 0 | L16: 00000000 | M16: 99999999
A17: 16 | B17: J9FA15000014 | C17: グルテニン | D17: ぐるてにん | E17: Glutenin | F17: 6 | G17: │ │ ├ グルテニン | H17: │ │ ├ Glutenin | J17: 1 | K17: 0 | L17: 00000000 | M17: 99999999
A18: 17 | B18: J9FA15000015 | C18: グリアジン | D18: ぐりあじん | E18: Gliadin | F18: 6 | G18: │ │ ├ グリアジン | H18: │ │ ├ Gliadin | J18: 1 | K18: 2 | L18: 00000000 | M18: 99999999
A19: 18 | B19: J9FA15000016 | C19: 小麦粉 | D19: こむぎこ | E19: Wheat flour | F19: 6 | G19: │ │ ├ 小麦粉 | H19: │ │ ├ Wheat flour | J19: 1 | K19: 0 | L19: 00000000 | M19: 99999999
A20: 19 | B20: J9FA15000017 | C20: 小麦でん粉 | D20: こむぎでんぷん | E20: Wheat starch | F20: 6 | G20: │ │ ├ 小麦でん粉 | H20: │ │ ├ Wheat starch | K20: 0 | L20: 00000000 | M20: 99999999
A21: 20 | B21: J9FA15000018 | C21: 特異的IgE ω-5 グリアジン | D21: とくいてきあいじーいーおめがふぁいぶぐりあじん | E21: Specific IgE omega-5 gliadin | F21: 6 | G21: │ │ └ 特異的IgE ω-5 グリアジン | H21: │ │ └ Specific IgE omega-5 gliadin | K21: 2 | L21: 00000000 | M21: 99999999
A22: 21 | B22: J9FA15110000 | C22: スペルト小麦 | D22: すぺるとこむぎ | E22: Spelt wheat | F22: 4 | G22: │ │ ├ スペルト小麦 | H22: │ │ ├ Spelt wheat | K22: 0 | L22: 00000000 | M22: 99999999
A23: 22 | B23: J9FA15120000 | C23: デュラム小麦 | D23: でゅらむこむぎ | E23: Durum wheat | F23: 4 | G23: │ │ ├ デュラム小麦 | H23: │ │ ├ Durum wheat | K23: 0 | L23: 00000000 | M23: 99999999
A24: 23 | B24: J9FA15120011 | C24: デュラムセモリナ | D24: でゅらむせもりな | E24: Durum semolina | F24: 6 | G24: │ │ │ └ デュラムセモリナ | H24: │ │ │ └ Durum semolina | K24: 0 | L24: 00000000 | M24: 99999999
A25: 24 | B25: J9FA15980000 | C25: 小麦（その他） | D25: こむぎ（そのた） | E25: Wheat (Other) | F25: 4 | G25: │ │ ├ 小麦（その他） | H25: │ │ ├ Wheat (Other) | K25: 0 | L25: 00000000 | M25: 99999999
A26: 25 | B26: J9FA15990000 | C26: 小麦（詳細不明） | D26: こむぎ（しょうさいふめい） | E26: Wheat (N.O.S) | F26: 4 | G26: │ │ └ 小麦（詳細不明） | H26: │ │ └ Wheat (N.O.S) | K26: 0 | L26: 00000000 | M26: 99999999
A27: 26 | B27: J9FA16000000 | C27: ライ麦 | D27: らいむぎ | E27: Rye | F27: 3 | G27: │ ├ ライ麦 | H27: │ ├ Rye | K27: 0 | L27: 00000000 | M27: 99999999
A28: 27 | B28: J9FA17000000 | C28: えん麦 | D28: えんむぎ | E28: Oats | F28: 3 | G28: │ ├ えん麦 | H28: │ ├ Oats | K28: 0 | L28: 00000000 | M28: 99999999
A29: 28 | B29: J9FA17000011 | C29: オートミール | D29: おーとみーる | E29: Oatmeal | F29: 6 | G29: │ │ └ オートミール | H29: │ │ └ Oatmeal | K29: 0 | L29: 00000000 | M29: 99999999
A30: 29 | B30: J9FA18000000 | C30: 精麦 | D30: せいばく | E30: Milled barley | F30: 3 | G30: │ ├ 精麦 | H30: │ ├ Milled barley | K30: 0 | L30: 00000000 | M30: 99999999
A31: 30 | B31: J9FA19000000 | C31: 雑穀 | D31: ざっこく | E31: Minor grains | F31: 3 | G31: │ ├ 雑穀 | H31: │ ├ Minor grains | K31: 0 | L31: 00000000 | M31: 99999999
A32: 31 | B32: J9FA19000011 | C32: 雑穀粉 | D32: ざっこくこ | E32: Millet flour | F32: 6 | G32: │ │ └ 雑穀粉 | H32: │ │ └ Millet flour | K32: 0 | L32: 00000000 | M32: 99999999
A33: 32 | B33: J9FA19110000 | C33: とうもろこし | D33: とうもろこし | E33: Corn | F33: 4 | G33: │ │ ├ とうもろこし | H33: │ │ ├ Corn | I33: 1 | J33: 1 | K33: 0 | L33: 00000000 | M33: 99999999
A34: 33 | B34: J9FA19110011 | C34: とうもろこし粉 | D34: とうもろこしこ | E34: Corn flour | F34: 6 | G34: │ │ │ ├ とうもろこし粉 | H34: │ │ │ ├ Corn flour | K34: 0 | L34: 00000000 | M34: 99999999
A35: 34 | B35: J9FA19110012 | C35: とうもろこしでん粉 | D35: とうもろこしでんぷん | E35: Corn starch | F35: 6 | G35: │ │ │ └ とうもろこしでん粉 | H35: │ │ │ └ Corn starch | K35: 0 | L35: 00000000 | M35: 99999999
A36: 35 | B36: J9FA19120000 | C36: あわ | D36: あわ | E36: Foxtail millet | F36: 4 | G36: │ │ ├ あわ | H36: │ │ ├ Foxtail millet | K36: 0 | L36: 00000000 | M36: 99999999
A37: 36 | B37: J9FA19130000 | C37: ひえ | D37: ひえ | E37: Japanese millet | F37: 4 | G37: │ │ ├ ひえ | H37: │ │ ├ Japanese millet | K37: 0 | L37: 00000000 | M37: 99999999
A38: 37 | B38: J9FA19140000 | C38: そば | D38: そば | E38: Buckwheat | F38: 4 | G38: │ │ ├ そば | H38: │ │ ├ Buckwheat | I38: 1 | J38: 1 | K38: 0 | L38: 00000000 | M38: 99999999
A39: 38 | B39: J9FA19140011 | C39: そば粉 | D39: そばこ | E39: Buckwheat flour | F39: 6 | G39: │ │ │ ├ そば粉 | H39: │ │ │ ├ Buckwheat flour | J39: 1 | K39: 0 | L39: 00000000 | M39: 99999999
A40: 39 | B40: J9FA19140012 | C40: そば茶 | D40: そばちゃ | E40: Buckwheat tea | F40: 6 | G40: │ │ │ ├ そば茶 | H40: │ │ │ ├ Buckwheat tea | K40: 2 | L40: 00000000 | M40: 99999999
...

Sheet Nコード表
A1: SEQ | B1: JFAGY code | C1: Allergen Term（JP） | D1: Furigana（JP） | E1: Allergen Term（EN） | F1: Level | G1: Ascii Tree（JP） | H1: Ascii Tree（EN） | I1: Main 100 | J1: Clinical Guideline | K1: CXGCATEGORY | L1: RECORDDATE | M1: ENDDATE
A2: 1130 | B2: 00N | C2: 非食品・非医薬品 | D2: ひしょくひん・ひいやくひん | E2: Non-food non-medication | F2: 1 | G2: 非食品・非医薬品 | H2: Non-food non-medication | I2: 1 | L2: 00000000 | M2: 99999999
A3: 1131 | B3: J9NJ00000000 | C3: 動物 | D3: どうぶつ | E3: Animals | F3: 2 | G3: ├ 動物 | H3: ├ Animals | I3: 1 | L3: 00000000 | M3: 99999999
A4: 1132 | B4: J9NJ11000000 | C4: 鳥類 | D4: ちょうるい | E4: Birds | F4: 3 | G4: │ ├ 鳥類 | H4: │ ├ Birds | I4: 1 | L4: 00000000 | M4: 99999999
A5: 1133 | B5: J9NJ11110000 | C5: アヒル | D5: あひる | E5: Duck | F5: 4 | G5: │ │ ├ アヒル | H5: │ │ ├ Duck | L5: 00000000 | M5: 99999999
A6: 1134 | B6: J9NJ11110011 | C6: アヒル羽毛 | D6: あひるうもう | E6: Duck feathers | F6: 6 | G6: │ │ │ └ アヒル羽毛 | H6: │ │ │ └ Duck feathers | L6: 00000000 | M6: 99999999
A7: 1135 | B7: J9NJ11120000 | C7: オウム | D7: おうむ | E7: Parrot | F7: 4 | G7: │ │ ├ オウム | H7: │ │ ├ Parrot | L7: 00000000 | M7: 99999999
A8: 1136 | B8: J9NJ11120011 | C8: オウム羽毛 | D8: おうむうもう | E8: Parrot feathers | F8: 6 | G8: │ │ │ └ オウム羽毛 | H8: │ │ │ └ Parrot feathers | L8: 00000000 | M8: 99999999
A9: 1137 | B9: J9NJ11130000 | C9: ガチョウ | D9: がちょう | E9: Goose | F9: 4 | G9: │ │ ├ ガチョウ | H9: │ │ ├ Goose | L9: 00000000 | M9: 99999999
A10: 1138 | B10: J9NJ11130011 | C10: ガチョウ羽毛 | D10: がちょううもう | E10: Goose feathers | F10: 6 | G10: │ │ │ └ ガチョウ羽毛 | H10: │ │ │ └ Goose feathers | L10: 00000000 | M10: 99999999
A11: 1139 | B11: J9NJ11140000 | C11: カナリヤ | D11: かなりや | E11: Canary | F11: 4 | G11: │ │ ├ カナリヤ | H11: │ │ ├ Canary | L11: 00000000 | M11: 99999999
A12: 1140 | B12: J9NJ11140011 | C12: カナリヤ羽毛 | D12: かなりやうもう | E12: Canary feathers | F12: 6 | G12: │ │ │ └ カナリヤ羽毛 | H12: │ │ │ └ Canary feathers | L12: 00000000 | M12: 99999999
A13: 1141 | B13: J9NJ11150000 | C13: ニワトリ | D13: にわとり | E13: Chicken | F13: 4 | G13: │ │ ├ ニワトリ | H13: │ │ ├ Chicken | L13: 00000000 | M13: 99999999
A14: 1142 | B14: J9NJ11150011 | C14: ニワトリ羽毛 | D14: にわとりうもう | E14: Chicken feathers | F14: 6 | G14: │ │ │ └ ニワトリ羽毛 | H14: │ │ │ └ Chicken feathers | L14: 00000000 | M14: 99999999
A15: 1143 | B15: J9NJ11160000 | C15: セキセイインコ | D15: せきせいいんこ | E15: Budgerigar | F15: 4 | G15: │ │ ├ セキセイインコ | H15: │ │ ├ Budgerigar | L15: 00000000 | M15: 99999999
A16: 1144 | B16: J9NJ11160011 | C16: セキセイインコ羽毛 | D16: せきせいいんこうもう | E16: Budgerigar feathers | F16: 6 | G16: │ │ │ ├ セキセイインコ羽毛 | H16: │ │ │ ├ Budgerigar feathers | L16: 00000000 | M16: 99999999
... A22: 1150 | B22: J9NJ11990000 | C22: 鳥類（詳細不明） | D22: ちょうるい（しょうさいふめい） | E22: Birds (N.O.S) | F22: 4 | G22: │ │ └ 鳥類（詳細不明） | H22: │ │ └ Birds (N.O.S) | L22: 00000000 | M22: 99999999
A23: 1151 | B23: J9NJ12000000 | C23: 哺乳類 | D23: ほにゅうるい | E23: Mammals | F23: 3 | G23: │ └ 哺乳類 | H23: │ └ Mammals | I23: 1 | L23: 00000000 | M23: 99999999
A24: 1152 | B24: J9NJ12110000 | C24: イヌ | D24: いぬ | E24: Dog | F24: 4 | G24: │ ├ イヌ | H24: │ ├ Dog | I24: 1 | J24: 1 | L24: 00000000 | M24: 99999999
A25: 1153 | B25: J9NJ12110011 | C25: イヌ上皮 | D25: いぬじょうひ | E25: Dog epithelium | F25: 6 | G25: │ │ ├ イヌ上皮 | H25: │ │ ├ Dog epithelium | L25: 00000000 | M25: 99999999
A26: 1154 | B26: J9NJ12110012 | C26: イヌ皮屑 | D26: いぬひせつ | E26: Dog dander | F26: 6 | G26: │ │ └ イヌ皮屑 | H26: │ │ └ Dog dander | J26: 1 | L26: 00000000 | M26: 99999999
A27: 1155 | B27: J9NJ12120000 | C27: ウサギ | D27: うさぎ | E27: Rabbit | F27: 4 | G27: │ ├ ウサギ | H27: │ ├ Rabbit | L27: 00000000 | M27: 99999999
A28: 1156 | B28: J9NJ12120011 | C28: ウサギ上皮 | D28: うさぎじょうひ | E28: Rabbit epithelium | F28: 6 | G28: │ │ ├ ウサギ上皮 | H28: │ │ ├ Rabbit epithelium | L28: 00000000 | M28: 99999999
A29: 1157 | B29: J9NJ12120012 | C29: ウサギ皮屑 | D29: うさぎひせつ | E29: Rabbit dander | F29: 6 | G29: │ │ └ ウサギ皮屑 | H29: │ │ └ Rabbit dander | J29: 1 | L29: 00000000 | M29: 99999999
A30: 1158 | B30: J9NJ12130000 | C30: ウシ | D30: うし | E30: Cow | F30: 4 | G30: │ ├ ウシ | H30: │ ├ Cow | L30: 00000000 | M30: 99999999
A31: 1159 | B31: J9NJ12130011 | C31: ウシ皮屑 | D31: うしひせつ | E31: Cow dander | F31: 6 | G31: │ │ └ ウシ皮屑 | H31: │ │ └ Cow dander | J31: 1 | L31: 00000000 | M31: 99999999
A32: 1160 | B32: J9NJ12140000 | C32: ウマ | D32: うま | E32: Horse | F32: 4 | G32: │ ├ ウマ | H32: │ ├ Horse | L32: 00000000 | M32: 99999999
A33: 1161 | B33: J9NJ12140011 | C33: ウマ皮屑 | D33: うまひせつ | E33: Horse dander | F33: 6 | G33: │ │ └ ウマ皮屑 | H33: │ │ └ Horse dander | J33: 1 | L33: 00000000 | M33: 99999999
A34: 1162 | B34: J9NJ12150000 | C34: ネコ | D34: ねこ | E34: Cat | F34: 4 | G34: │ ├ ネコ | H34: │ ├ Cat | I34: 1 | L34: 00000000 | M34: 99999999
A35: 1163 | B35: J9NJ12150011 | C35: ネコ上皮 | D35: ねこじょうひ | E35: Cat epithelium | F35: 6 | G35: │ │ ├ ネコ上皮 | H35: │ │ ├ Cat epithelium | L35: 00000000 | M35: 99999999
A36: 1164 | B36: J9NJ12150012 | C36: ネコ皮屑 | D36: ねこひせつ | E36: Cat dander | F36: 6 | G36: │ │ └ ネコ皮屑 | H36: │ │ └ Cat dander | J36: 1 | L36: 00000000 | M36: 99999999
A37: 1165 | B37: J9NJ12160000 | C37: ハムスター | D37: はむすたー | E37: Hamster | F37: 4 | G37: │ ├ ハムスター | H37: │ ├ Hamster | L37: 00000000 | M37: 99999999
A38: 1166 | B38: J9NJ12160011 | C38: ハムスター上皮 | D38: はむすたーじょうひ | E38: Hamster epithelium | F38: 6 | G38: │ │ └ ハムスター上皮 | H38: │ │ └ Hamster epithelium | L38: 00000000 | M38: 99999999
A39: 1167 | B39: J9NJ12170000 | C39: ヒツジ | D39: ひつじ | E39: Sheep | F39: 4 | G39: │ ├ ヒツジ | H39: │ ├ Sheep | L39: 00000000 | M39: 99999999
A40: 1168 | B40: J9NJ12170011 | C40: ヒツジ上皮 | D40: ひつじじょうひ | E40: Sheep epithelium | F40: 6 | G40: │ │ └ ヒツジ上皮 | H40: │ │ └ Sheep epithelium | L40: 00000000 | M40: 99999999
A41: 1169 | B41: J9NJ12180000 | C41: ブタ | D41: ぶた | E41: Pig | F41: 4 | G41: │ ├ ブタ | H41: │ ├ Pig | L41: 00000000 | M41: 99999999
A42: 1170 | B42: J9NJ12180011 | C42: ブタ上皮 | D42: ぶたじょうひ | E42: Pig epithelium | F42: 6 | G42: │ │ └ ブタ上皮 | H42: │ │ └ Pig epithelium | L42: 00000000 | M42: 99999999
A43: 1171 | B43: J9NJ12190000 | C43: マウス | D43: まうす | E43: Mouse | F43: 4 | G43: │ ├ マウス | H43: │ ├ Mouse | J43: 1 | L43: 00000000 | M43: 99999999
A44: 1172 | B44: J9NJ12190011 | C44: マウス上皮 | D44: まうすじょうひ | E44: Mouse epithelium | F44: 6 | G44: │ │ ├ マウス上皮 | H44: │ │ ├ Mouse epithelium | L44: 00000000 | M44: 99999999
A45: 1173 | B45: J9NJ12190012 | C45: マウス皮屑 | D45: まうすひせつ | E45: Mouse dander | F45: 6 | G45: │ │ ├ マウス皮屑 | H45: │ │ ├ Mouse dander | L45: 00000000 | M45: 99999999
...

Sheet F-FSH
A1: 相対レベル | B1: FSH
A2: 1 | B2: =REPT(" ",(A2-1)*2)&"* #"&Fコード表!B2&" """&Fコード表!C2&"""" -> * #00F "食品"
A3: =IF(Fコード表!F3>Fコード表!F2,Fコード表!F2+1,IF(Fコード表!F3=Fコード表!F2,A2,Fコード表!F3)) -> 2 | B3: =REPT(" ",(A3-1)*2)&"* #"&Fコード表!B3&" """&Fコード表!C3&"""" -> * #J9FA00000000 "農産食品"
A4: =IF(Fコード表!F4>Fコード表!F3,Fコード表!F3+1,IF(Fコード表!F4=Fコード表!F3,A3,Fコード表!F4)) -> 3 | B4: =REPT(" ",(A4-1)*2)&"* #"&Fコード表!B4&" """&Fコード表!C4&"""" -> * #J9FA11000000 "もみ"
A5: =IF(Fコード表!F5>Fコード表!F4,Fコード表!F4+1,IF(Fコード表!F5=Fコード表!F4,A4,Fコード表!F5)) -> 3 | B5: =REPT(" ",(A5-1)*2)&"* #"&Fコード表!B5&" """&Fコード表!C5&"""" -> * #J9FA12000000 "玄米"
A6: =IF(Fコード表!F6>Fコード表!F5,Fコード表!F5+1,IF(Fコード表!F6=Fコード表!F5,A5,Fコード表!F6)) -> 4 | B6: =REPT(" ",(A6-1)*2)&"* #"&Fコード表!B6&" """&Fコード表!C6&"""" -> * #J9FA12000011 "米ぬか"
A7: =IF(Fコード表!F7>Fコード表!F6,Fコード表!F6+1,IF(Fコード表!F7=Fコード表!F6,A6,Fコード表!F7)) -> 3 | B7: =REPT(" ",(A7-1)*2)&"* #"&Fコード表!B7&" """&Fコード表!C7&"""" -> * #J9FA13000000 "白米"
A8: =IF(Fコード表!F8>Fコード表!F7,Fコード表!F7+1,IF(Fコード表!F8=Fコード表!F7,A7,Fコード表!F8)) -> 4 | B8: =REPT(" ",(A8-1)*2)&"* #"&Fコード表!B8&" """&Fコード表!C8&"""" -> * #J9FA13000011 "もち"
A9: =IF(Fコード表!F9>Fコード表!F8,Fコード表!F8+1,IF(Fコード表!F9=Fコード表!F8,A8,Fコード表!F9)) -> 4 | B9: =REPT(" ",(A9-1)*2)&"* #"&Fコード表!B9&" """&Fコード表!C9&"""" -> * #J9FA13000012 "米粉"
A10: =IF(Fコード表!F10>Fコード表!F9,Fコード表!F9+1,IF(Fコード表!F10=Fコード表!F9,A9,Fコード表!F10)) -> 3 | B10: =REPT(" ",(A10-1)*2)&"* #"&Fコード表!B10&" """&Fコード表!C10&"""" -> * #J9FA14000000 "大麦"
A11: =IF(Fコード表!F11>Fコード表!F10,Fコード表!F10+1,IF(Fコード表!F11=Fコード表!F10,A10,Fコード表!F11)) -> 4 | B11: =REPT(" ",(A11-1)*2)&"* #"&Fコード表!B11&" """&Fコード表!C11&"""" -> * #J9FA14000011 "大麦粉"
A12: =IF(Fコード表!F12>Fコード表!F11,Fコード表!F11+1,IF(Fコード表!F12=Fコード表!F11,A11,Fコード表!F12)) -> 4 | B12: =REPT(" ",(A12-1)*2)&"* #"&Fコード表!B12&" """&Fコード表!C12&"""" -> * #J9FA14000012 "麦茶"
A13: =IF(Fコード表!F13>Fコード表!F12,Fコード表!F12+1,IF(Fコード表!F13=Fコード表!F12,A12,Fコード表!F13)) -> 3 | B13: =REPT(" ",(A13-1)*2)&"* #"&Fコード表!B13&" """&Fコード表!C13&"""" -> * #J9FA15000000 "小麦"
A14: =IF(Fコード表!F14>Fコード表!F13,Fコード表!F13+1,IF(Fコード表!F14=Fコード表!F13,A13,Fコード表!F14)) -> 4 | B14: =REPT(" ",(A14-1)*2)&"* #"&Fコード表!B14&" """&Fコード表!C14&"""" -> * #J9FA15000011 "小麦ふすま"
... A1131: =IF(Fコード表!F1131>Fコード表!F1130,Fコード表!F1130+1,IF(Fコード表!F1131=Fコード表!F1130,A1130,Fコード表!F1131)) -> 3 | B1131: =REPT(" ",(A1131-1)*2)&"* #"&Fコード表!B1131&" """&Fコード表!C1131&"""" -> * #J9FH14000000 "氷"

Sheet N-FSH
A1: 相対レベル | B1: FSH
A2: 1 | B2: =REPT(" ",(A2-1)*2)&"* #"&Nコード表!B2&" """&Nコード表!C2&"""" -> * #00N "非食品・非医薬品"
A3: =IF(Nコード表!F3>Nコード表!F2,Nコード表!F2+1,IF(Nコード表!F3=Nコード表!F2,A2,Nコード表!F3)) -> 2 | B3: =REPT(" ",(A3-1)*2)&"* #"&Nコード表!B3&" """&Nコード表!C3&"""" -> * #J9NJ00000000 "動物"
A4: =IF(Nコード表!F4>Nコード表!F3,Nコード表!F3+1,IF(Nコード表!F4=Nコード表!F3,A3,Nコード表!F4)) -> 3 | B4: =REPT(" ",(A4-1)*2)&"* #"&Nコード表!B4&" """&Nコード表!C4&"""" -> * #J9NJ11000000 "鳥類"
A5: =IF(Nコード表!F5>Nコード表!F4,Nコード表!F4+1,IF(Nコード表!F5=Nコード表!F4,A4,Nコード表!F5)) -> 4 | B5: =REPT(" ",(A5-1)*2)&"* #"&Nコード表!B5&" """&Nコード表!C5&"""" -> * #J9NJ11110000 "アヒル"
A6: =IF(Nコード表!F6>Nコード表!F5,Nコード表!F5+1,IF(Nコード表!F6=Nコード表!F5,A5,Nコード表!F6)) -> 5 | B6: =REPT(" ",(A6-1)*2)&"* #"&Nコード表!B6&" """&Nコード表!C6&"""" -> * #J9NJ11110011 "アヒル羽毛"
A7: =IF(Nコード表!F7>Nコード表!F6,Nコード表!F6+1,IF(Nコード表!F7=Nコード表!F6,A6,Nコード表!F7)) -> 4 | B7: =REPT(" ",(A7-1)*2)&"* #"&Nコード表!B7&" """&Nコード表!C7&"""" -> * #J9NJ11120000 "オウム"
A8: =IF(Nコード表!F8>Nコード表!F7,Nコード表!F7+1,IF(Nコード表!F8=Nコード表!F7,A7,Nコード表!F8)) -> 5 | B8: =REPT(" ",(A8-1)*2)&"* #"&Nコード表!B8&" """&Nコード表!C8&"""" -> * #J9NJ11120011 "オウム羽毛"
A9: =IF(Nコード表!F9>Nコード表!F8,Nコード表!F8+1,IF(Nコード表!F9=Nコード表!F8,A8,Nコード表!F9)) -> 4 | B9: =REPT(" ",(A9-1)*2)&"* #"&Nコード表!B9&" """&Nコード表!C9&"""" -> * #J9NJ11130000 "ガチョウ"
A10: =IF(Nコード表!F10>Nコード表!F9,Nコード表!F9+1,IF(Nコード表!F10=Nコード表!F9,A9,Nコード表!F10)) -> 5 | B10: =REPT(" ",(A10-1)*2)&"* #"&Nコード表!B10&" """&Nコード表!C10&"""" -> * #J9NJ11130011 "ガチョウ羽毛"
A11: =IF(Nコード表!F11>Nコード表!F10,Nコード表!F10+1,IF(Nコード表!F11=Nコード表!F10,A10,Nコード表!F11)) -> 4 | B11: =REPT(" ",(A11-1)*2)&"* #"&Nコード表!B11&" """&Nコード表!C11&"""" -> * #J9NJ11140000 "カナリヤ"
A12: =IF(Nコード表!F12>Nコード表!F11,Nコード表!F11+1,IF(Nコード表!F12=Nコード表!F11,A11,Nコード表!F12)) -> 5 | B12: =REPT(" ",(A12-1)*2)&"* #"&Nコード表!B12&" """&Nコード表!C12&"""" -> * #J9NJ11140011 "カナリヤ羽毛"
A13: =IF(Nコード表!F13>Nコード表!F12,Nコード表!F12+1,IF(Nコード表!F13=Nコード表!F12,A12,Nコード表!F13)) -> 4 | B13: =REPT(" ",(A13-1)*2)&"* #"&Nコード表!B13&" """&Nコード表!C13&"""" -> * #J9NJ11150000 "ニワトリ"
A14: =IF(Nコード表!F14>Nコード表!F13,Nコード表!F13+1,IF(Nコード表!F14=Nコード表!F13,A13,Nコード表!F14)) -> 5 | B14: =REPT(" ",(A14-1)*2)&"* #"&Nコード表!B14&" """&Nコード表!C14&"""" -> * #J9NJ11150011 "ニワトリ羽毛"
... A609: =IF(Nコード表!F609>Nコード表!F608,Nコード表!F608+1,IF(Nコード表!F609=Nコード表!F608,A608,Nコード表!F609)) -> 4 | B609: =REPT(" ",(A609-1)*2)&"* #"&Nコード表!B609&" """&Nコード表!C609&"""" -> * #J9NU11990000 "酸化防止剤（詳細不明）"
