Workbook

Sheet JFAGY（食品・非食品ICD11）V8
A1: SEQ | B1: 商品分類番号 | C1: 商品分類番号０埋め | D1: C | E1: D | F1: E | G1: F | H1: G | I1: H | J1: I | K1: J | L1: JFAGY-Value | M1: 名称 | N1: メタコード | O1: 第１層 | P1: 第１層 | Q1: 第２層_1 | R1: 第２層_2 | S1: 第２層 | T1: 第２層 | U1: 第３層_1 | V1: 第３層_２ | W1: 第３層 | X1: 第３層 | Y1: 第４層_１ | Z1: 第４層_２ | AA1: 第４層 | AB1: 第４層 | AC1: 枝番1 | AD1: 枝番2 | AE1: アレルゲン名称（商品分類の用語） | AF1: アレルゲン名称（PT） | AG1: 削除フラグ | AH1: 不要？ | AI1: メモ | AJ1: 商品分類以外に出現する用語 | AK1: 作業用番号 | AL1: 分類番号 | AM1: 移動 | AN1: JFAGY | AO1: 同義語 | AP1: セット | AQ1: ICD11_URL | AR1: 商品分類表 | AS1: JLAC10 | AT1: ICD10 | AU1: 食品表示法 | AV1: アレルギー総合ガイドライン2019 | AW1: アレルギー疾患の手引き 2020版 | AX1: 食物アレルギーガイドライン2016 | AY1: ジャパニーズスタンダードアレルゲン 2015 | AZ1: アレルギー検査キット（アンブロシア） | BA1: アレルギー検査キット（おおしま皮膚科） | BB1: アレルギー検査キット（US BioTek Laboratories） | BC1: 接触皮膚炎診療ガイドライン 2020 | BD1: ICD11_Allergents | BE1: 出典数合計
A2: 0 | L2: J9F000000000 | M2: 食品 | N2: J9F | O2: 0 | P2: 食品 | Q2: 0 | R2: 0 | S2: 食品 | T2: 食品 | U2: 0 | V2: 0 | W2: 食品 | X2: 食品 | Y2: 0 | Z2: 0 | AA2: 食品 | AB2: 食品 | AC2: 0 | AD2: 0 | AE2: 食品 | AF2: 食品 | AJ2: =IF(OR(AS2=1,AT2=1,AU2=1,AV2=1,AW2=1,AX2=1,AY2=1,AZ2=1,BA2=1,BB2=1,BC2=1,BD2=1),TRUE,FALSE) -> FALSE | AK2: =O2&Q2&R2&U2&V2&Y2&Z2&AC2&AD2 -> 000000000 | AN2: =N2&AK2 -> J9F000000000 | AR2: =IF(AL2<>"",1,"") | AS2: =IF(IFERROR(VLOOKUP(AE2,#REF!,1,0),"")<>"",1,"") | AT2: =IF(IFERROR(VLOOKUP(AE2,#REF!,1,0),"")<>"",1,"") | AU2: =IF(IFERROR(VLOOKUP(AE2,#REF!,1,0),"")<>"",1,"") | AV2: =IF(IFERROR(VLOOKUP(AE2,#REF!,1,0),"")<>"",1,"") | AW2: =IF(IFERROR(VLOOKUP(AE2,#REF!,1,0),"")<>"",1,"") | AX2: =IF(IFERROR(VLOOKUP(AE2,#REF!,1,0),"")<>"",1,"") | AY2: =IF(IFERROR(VLOOKUP(AE2,#REF!,1,0),"")<>"",1,"") | AZ2: =IF(IFERROR(VLOOKUP(AE2,#REF!,1,0),"")<>"",1,"") | BA2: =IF(IFERROR(VLOOKUP(AE2,#REF!,1,0),"")<>"",1,"") | BB2: =IF(IFERROR(VLOOKUP(AE2,#REF!,1,0),"")<>"",1,"") | BC2: =IF(IFERROR(VLOOKUP(AE2,#REF!,1,0),"")<>"",1,"") | BD2: =IF(IFERROR(VLOOKUP(AE2,#REF!,1,0),"")<>"",1,"") | BE2: =SUM(AR2:BD2) -> 0
A3: 1 | B3: 69 | C3: =LEFT(B3 & "000000000", 9) -> 690000000 | D3: =MID(C3,1,2) -> 69 | E3: =MID(C3,3,1) -> 0 | F3: =MID(C3,4,1) -> 0 | G3: =MID(C3,5,1) -> 0 | H3: =MID(C3,6,1) -> 0 | I3: =MID(C3,7,1) -> 0 | J3: =MID(C3,8,1) -> 0 | K3: =MID(C3,9,1) -> 0 | L3: J9FA00000000 | M3: 農産食品 | N3: J9F | O3: A | P3: 農産食品 | Q3: 0 | R3: 0 | S3: 農産食品 | T3: 農産食品 | U3: 0 | V3: 0 | W3: 農産食品 | X3: 農産食品 | Y3: 0 | Z3: 0 | AA3: 農産食品 | AB3: 農産食品 | AC3: 0 | AD3: 0 | AE3: 農産食品 | AF3: 農産食品 | AJ3: =IF(OR(AS3=1,AT3=1,AU3=1,AV3=1,AW3=1,AX3=1,AY3=1,AZ3=1,BA3=1,BB3=1,BC3=1,BD3=1),TRUE,FALSE) -> FALSE | AK3: =O3&Q3&R3&U3&V3&Y3&Z3&AC3&AD3 -> A00000000 | AL3: 69 | AM3: =C3<>AK3 -> TRUE | AN3: =N3&AK3 -> J9FA00000000 | AR3: =IF(AL3<>"",1,"") -> 1 | AS3: =IF(IFERROR(VLOOKUP(AE3,#REF!,1,0),"")<>"",1,"") | AT3: =IF(IFERROR(VLOOKUP(AE3,#REF!,1,0),"")<>"",1,"") | AU3: =IF(IFERROR(VLOOKUP(AE3,#REF!,1,0),"")<>"",1,"") | AV3: =IF(IFERROR(VLOOKUP(AE3,#REF!,1,0),"")<>"",1,"") | AW3: =IF(IFERROR(VLOOKUP(AE3,#REF!,1,0),"")<>"",1,"") | AX3: =IF(IFERROR(VLOOKUP(AE3,#REF!,1,0),"")<>"",1,"") | AY3: =IF(IFERROR(VLOOKUP(AE3,#REF!,1,0),"")<>"",1,"") | AZ3: =IF(IFERROR(VLOOKUP(AE3,#REF!,1,0),"")<>"",1,"") | BA3: =IF(IFERROR(VLOOKUP(AE3,#REF!,1,0),"")<>"",1,"") | BB3: =IF(IFERROR(VLOOKUP(AE3,#REF!,1,0),"")<>"",1,"") | BC3: =IF(IFERROR(VLOOKUP(AE3,#REF!,1,0),"")<>"",1,"") | BD3: =IF(IFERROR(VLOOKUP(AE3,#REF!,1,0),"")<>"",1,"") | BE3: =SUM(AR3:BD3) -> 1
A4: 2 | B4: 691 | C4: =LEFT(B4 & "000000000", 9) -> 691000000 | D4: =MID(C4,1,2) -> 69 | E4: =MID(C4,3,1) -> 1 | F4: =MID(C4,4,1) -> 0 | G4: =MID(C4,5,1) -> 0 | H4: =MID(C4,6,1) -> 0 | I4: =MID(C4,7,1) -> 0 | J4: =MID(C4,8,1) -> 0 | K4: =MID(C4,9,1) -> 0 | M4: 米穀 | O4: A | P4: 農産食品 | Q4: 1 | S4: 米穀 | T4: 米穀 | U4: 0 | V4: 0 | X4: 米穀 | Y4: 0 | Z4: 0 | AB4: 米穀 | AC4: 0 | AD4: 0 | AE4: 米穀 | AG4: 1 | AK4: =O4&Q4&#REF!&U4&V4&Y4&Z4&AC4&AD4 -> #REF! | AL4: 691 | AM4: =C4<>AK4 -> #REF! | AR4: =IF(AL4<>"",1,"") -> 1 | AS4: =IF(IFERROR(VLOOKUP(AE4,#REF!,1,0),"")<>"",1,"") | AT4: =IF(IFERROR(VLOOKUP(AE4,#REF!,1,0),"")<>"",1,"") | AU4: =IF(IFERROR(VLOOKUP(AE4,#REF!,1,0),"")<>"",1,"") | AV4: =IF(IFERROR(VLOOKUP(AE4,#REF!,1,0),"")<>"",1,"") | AW4: =IF(IFERROR(VLOOKUP(AE4,#REF!,1,0),"")<>"",1,"") | AX4: =IF(IFERROR(VLOOKUP(AE4,#REF!,1,0),"")<>"",1,"") | AY4: =IF(IFERROR(VLOOKUP(AE4,#REF!,1,0),"")<>"",1,"") | AZ4: =IF(IFERROR(VLOOKUP(AE4,#REF!,1,0),"")<>"",1,"") | BA4: =IF(IFERROR(VLOOKUP(AE4,#REF!,1,0),"")<>"",1,"") | BB4: =IF(IFERROR(VLOOKUP(AE4,#REF!,1,0),"")<>"",1,"") | BC4: =IF(IFERROR(VLOOKUP(AE4,#REF!,1,0),"")<>"",1,"") | BD4: =IF(IFERROR(VLOOKUP(AE4,#REF!,1,0),"")<>"",1,"") | BE4: =SUM(AR4:BD4) -> 1
A5: 3 | B5: 6911 | C5: =LEFT(B5 & "000000000", 9) -> 691100000 | D5: =MID(C5,1,2) -> 69 | E5: =MID(C5,3,1) -> 1 | F5: =MID(C5,4,1) -> 1 | G5: =MID(C5,5,1) -> 0 | H5: =MID(C5,6,1) -> 0 | I5: =MID(C5,7,1) -> 0 | J5: =MID(C5,8,1) -> 0 | K5: =MID(C5,9,1) -> 0 | L5: J9FA11000000 | M5: もみ | N5: J9F | O5: A | P5: 農産食品 | Q5: 1 | R5: 1 | S5: もみ | T5: もみ | U5: 0 | V5: 0 | W5: もみ | X5: もみ | Y5: 0 | Z5: 0 | AA5: もみ | AB5: もみ | AC5: 0 | AD5: 0 | AE5: もみ | AF5: もみ | AJ5: =IF(OR(AS5=1,AT5=1,AU5=1,AV5=1,AW5=1,AX5=1,AY5=1,AZ5=1,BA5=1,BB5=1,BC5=1,BD5=1),TRUE,FALSE) -> FALSE | AK5: =O5&Q5&R5&U5&V5&Y5&Z5&AC5&AD5 -> A11000000 | AL5: 6911 | AM5: =C5<>AK5 -> TRUE | AN5: =N5&AK5 -> J9FA11000000 | AO5: うるちもみ、もちもみ | AR5: =IF(AL5<>"",1,"") -> 1 | AS5: =IF(IFERROR(VLOOKUP(AE5,#REF!,1,0),"")<>"",1,"") | AT5: =IF(IFERROR(VLOOKUP(AE5,#REF!,1,0),"")<>"",1,"") | AU5: =IF(IFERROR(VLOOKUP(AE5,#REF!,1,0),"")<>"",1,"") | AV5: =IF(IFERROR(VLOOKUP(AE5,#REF!,1,0),"")<>"",1,"") | AW5: =IF(IFERROR(VLOOKUP(AE5,#REF!,1,0),"")<>"",1,"") | AX5: =IF(IFERROR(VLOOKUP(AE5,#REF!,1,0),"")<>"",1,"") | AY5: =IF(IFERROR(VLOOKUP(AE5,#REF!,1,0),"")<>"",1,"") | AZ5: =IF(IFERROR(VLOOKUP(AE5,#REF!,1,0),"")<>"",1,"") | BA5: =IF(IFERROR(VLOOKUP(AE5,#REF!,1,0),"")<>"",1,"") | BB5: =IF(IFERROR(VLOOKUP(AE5,#REF!,1,0),"")<>"",1,"") | BC5: =IF(IFERROR(VLOOKUP(AE5,#REF!,1,0),"")<>"",1,"") | BD5: =IF(IFERROR(VLOOKUP(AE5,#REF!,1,0),"")<>"",1,"") | BE5: =SUM(AR5:BD5) -> 1
A6: 4 | B6: 69111 | C6: =LEFT(B6 & "000000000", 9) -> 691110000 | D6: =MID(C6,1,2) -> 69 | E6: =MID(C6,3,1) -> 1 | F6: =MID(C6,4,1) -> 1 | G6: =MID(C6,5,1) -> 1 | H6: =MID(C6,6,1) -> 0 | I6: =MID(C6,7,1) -> 0 | J6: =MID(C6,8,1) -> 0 | K6: =MID(C6,9,1) -> 0 | L6: J9FA11110000 | M6: 国内産普通もみ | N6: J9F | O6: A | P6: 農産食品 | Q6: 1 | R6: 1 | S6: もみ | T6: もみ | U6: 1 | V6: 1 | W6: 国内産普通もみ | X6: 国内産普通もみ | Y6: 0 | Z6: 0 | AA6: 国内産普通もみ | AB6: 国内産普通もみ | AC6: 0 | AD6: 0 | AE6: 国内産普通もみ | AF6: 国内産普通もみ | AH6: 1 | AJ6: =IF(OR(AS6=1,AT6=1,AU6=1,AV6=1,AW6=1,AX6=1,AY6=1,AZ6=1,BA6=1,BB6=1,BC6=1,BD6=1),TRUE,FALSE) -> FALSE | AK6: =O6&Q6&R6&U6&V6&Y6&Z6&AC6&AD6 -> A11110000 | AL6: 69111 | AM6: =C6<>AK6 -> TRUE | AN6: =N6&AK6 -> J9FA11110000 | AR6: =IF(AL6<>"",1,"") -> 1 | AS6: =IF(IFERROR(VLOOKUP(AE6,#REF!,1,0),"")<>"",1,"") | AT6: =IF(IFERROR(VLOOKUP(AE6,#REF!,1,0),"")<>"",1,"") | AU6: =IF(IFERROR(VLOOKUP(AE6,#REF!,1,0),"")<>"",1,"") | AV6: =IF(IFERROR(VLOOKUP(AE6,#REF!,1,0),"")<>"",1,"") | AW6: =IF(IFERROR(VLOOKUP(AE6,#REF!,1,0),"")<>"",1,"") | AX6: =IF(IFERROR(VLOOKUP(AE6,#REF!,1,0),"")<>"",1,"") | AY6: =IF(IFERROR(VLOOKUP(AE6,#REF!,1,0),"")<>"",1,"") | AZ6: =IF(IFERROR(VLOOKUP(AE6,#REF!,1,0),"")<>"",1,"") | BA6: =IF(IFERROR(VLOOKUP(AE6,#REF!,1,0),"")<>"",1,"") | BB6: =IF(IFERROR(VLOOKUP(AE6,#REF!,1,0),"")<>"",1,"") | BC6: =IF(IFERROR(VLOOKUP(AE6,#REF!,1,0),"")<>"",1,"") | BD6: =IF(IFERROR(VLOOKUP(AE6,#REF!,1,0),"")<>"",1,"") | BE6: =SUM(AR6:BD6) -> 1
A7: 5 | B7: 691111 | C7: =LEFT(B7 & "000000000", 9) -> 691111000 | D7: =MID(C7,1,2) -> 69 | E7: =MID(C7,3,1) -> 1 | F7: =MID(C7,4,1) -> 1 | G7: =MID(C7,5,1) -> 1 | H7: =MID(C7,6,1) -> 1 | I7: =MID(C7,7,1) -> 0 | J7: =MID(C7,8,1) -> 0 | K7: =MID(C7,9,1) -> 0 | L7: J9FA11120000 | M7: 水稲うるちもみ | N7: J9F | O7: A | P7: 農産食品 | Q7: 1 | R7: 1 | S7: もみ | T7: もみ | U7: 1 | V7: 2 | W7: 水稲うるちもみ | X7: 水稲うるちもみ | Y7: 0 | Z7: 0 | AA7: 水稲うるちもみ | AB7: 水稲うるちもみ | AC7: 0 | AD7: 0 | AE7: 水稲うるちもみ | AF7: 水稲うるちもみ | AH7: 1 | AJ7: =IF(OR(AS7=1,AT7=1,AU7=1,AV7=1,AW7=1,AX7=1,AY7=1,AZ7=1,BA7=1,BB7=1,BC7=1,BD7=1),TRUE,FALSE) -> FALSE | AK7: =O7&Q7&R7&U7&V7&Y7&Z7&AC7&AD7 -> A11120000 | AL7: 691111 | AM7: =C7<>AK7 -> TRUE | AN7: =N7&AK7 -> J9FA11120000 | AR7: =IF(AL7<>"",1,"") -> 1 | AS7: =IF(IFERROR(VLOOKUP(AE7,#REF!,1,0),"")<>"",1,"") | AT7: =IF(IFERROR(VLOOKUP(AE7,#REF!,1,0),"")<>"",1,"") | AU7: =IF(IFERROR(VLOOKUP(AE7,#REF!,1,0),"")<>"",1,"") | AV7: =IF(IFERROR(VLOOKUP(AE7,#REF!,1,0),"")<>"",1,"") | AW7: =IF(IFERROR(VLOOKUP(AE7,#REF!,1,0),"")<>"",1,"") | AX7: =IF(IFERROR(VLOOKUP(AE7,#REF!,1,0),"")<>"",1,"") | AY7: =IF(IFERROR(VLOOKUP(AE7,#REF!,1,0),"")<>"",1,"") | AZ7: =IF(IFERROR(VLOOKUP(AE7,#REF!,1,0),"")<>"",1,"") | BA7: =IF(IFERROR(VLOOKUP(AE7,#REF!,1,0),"")<>"",1,"") | BB7: =IF(IFERROR(VLOOKUP(AE7,#REF!,1,0),"")<>"",1,"") | BC7: =IF(IFERROR(VLOOKUP(AE7,#REF!,1,0),"")<>"",1,"") | BD7: =IF(IFERROR(VLOOKUP(AE7,#REF!,1,0),"")<>"",1,"") | BE7: =SUM(AR7:BD7) -> 1
A8: 6 | B8: 691112 | C8: =LEFT(B8 & "000000000", 9) -> 691112000 | D8: =MID(C8,1,2) -> 69 | E8: =MID(C8,3,1) -> 1 | F8: =MID(C8,4,1) -> 1 | G8: =MID(C8,5,1) -> 1 | H8: =MID(C8,6,1) -> 2 | I8: =MID(C8,7,1) -> 0 | J8: =MID(C8,8,1) -> 0 | K8: =MID(C8,9,1) -> 0 | L8: J9FA11130000 | M8: 水稲もちもみ | N8: J9F | O8: A | P8: 農産食品 | Q8: 1 | R8: 1 | S8: もみ | T8: もみ | U8: 1 | V8: 3 | W8: 水稲もちもみ | X8: 水稲もちもみ | Y8: 0 | Z8: 0 | AA8: 水稲もちもみ | AB8: 水稲もちもみ | AC8: 0 | AD8: 0 | AE8: 水稲もちもみ | AF8: 水稲もちもみ | AH8: 1 | AJ8: =IF(OR(AS8=1,AT8=1,AU8=1,AV8=1,AW8=1,AX8=1,AY8=1,AZ8=1,BA8=1,BB8=1,BC8=1,BD8=1),TRUE,FALSE) -> FALSE | AK8: =O8&Q8&R8&U8&V8&Y8&Z8&AC8&AD8 -> A11130000 | AL8: 691112 | AM8: =C8<>AK8 -> TRUE | AN8: =N8&AK8 -> J9FA11130000 | AR8: =IF(AL8<>"",1,"") -> 1 | AS8: =IF(IFERROR(VLOOKUP(AE8,#REF!,1,0),"")<>"",1,"") | AT8: =IF(IFERROR(VLOOKUP(AE8,#REF!,1,0),"")<>"",1,"") | AU8: =IF(IFERROR(VLOOKUP(AE8,#REF!,1,0),"")<>"",1,"") | AV8: =IF(IFERROR(VLOOKUP(AE8,#REF!,1,0),"")<>"",1,"") | AW8: =IF(IFERROR(VLOOKUP(AE8,#REF!,1,0),"")<>"",1,"") | AX8: =IF(IFERROR(VLOOKUP(AE8,#REF!,1,0),"")<>"",1,"") | AY8: =IF(IFERROR(VLOOKUP(AE8,#REF!,1,0),"")<>"",1,"") | AZ8: =IF(IFERROR(VLOOKUP(AE8,#REF!,1,0),"")<>"",1,"") | BA8: =IF(IFERROR(VLOOKUP(AE8,#REF!,1,0),"")<>"",1,"") | BB8: =IF(IFERROR(VLOOKUP(AE8,#REF!,1,0),"")<>"",1,"") | BC8: =IF(IFERROR(VLOOKUP(AE8,#REF!,1,0),"")<>"",1,"") | BD8: =IF(IFERROR(VLOOKUP(AE8,#REF!,1,0),"")<>"",1,"") | BE8: =SUM(AR8:BD8) -> 1
A9: 7 | B9: 691113 | C9: =LEFT(B9 & "000000000", 9) -> 691113000 | D9: =MID(C9,1,2) -> 69 | E9: =MID(C9,3,1) -> 1 | F9: =MID(C9,4,1) -> 1 | G9: =MID(C9,5,1) -> 1 | H9: =MID(C9,6,1) -> 3 | I9: =MID(C9,7,1) -> 0 | J9: =MID(C9,8,1) -> 0 | K9: =MID(C9,9,1) -> 0 | L9: J9FA11140000 | M9: 陸稲うるちもみ | N9: J9F | O9: A | P9: 農産食品 | Q9: 1 | R9: 1 | S9: もみ | T9: もみ | U9: 1 | V9: 4 | W9: 陸稲うるちもみ | X9: 陸稲うるちもみ | Y9: 0 | Z9: 0 | AA9: 陸稲うるちもみ | AB9: 陸稲うるちもみ | AC9: 0 | AD9: 0 | AE9: 陸稲うるちもみ | AF9: 陸稲うるちもみ | AH9: 1 | AJ9: =IF(OR(AS9=1,AT9=1,AU9=1,AV9=1,AW9=1,AX9=1,AY9=1,AZ9=1,BA9=1,BB9=1,BC9=1,BD9=1),TRUE,FALSE) -> FALSE | AK9: =O9&Q9&R9&U9&V9&Y9&Z9&AC9&AD9 -> A11140000 | AL9: 691113 | AM9: =C9<>AK9 -> TRUE | AN9: =N9&AK9 -> J9FA11140000 | AR9: =IF(AL9<>"",1,"") -> 1 | AS9: =IF(IFERROR(VLOOKUP(AE9,#REF!,1,0),"")<>"",1,"") | AT9: =IF(IFERROR(VLOOKUP(AE9,#REF!,1,0),"")<>"",1,"") | AU9: =IF(IFERROR(VLOOKUP(AE9,#REF!,1,0),"")<>"",1,"") | AV9: =IF(IFERROR(VLOOKUP(AE9,#REF!,1,0),"")<>"",1,"") | AW9: =IF(IFERROR(VLOOKUP(AE9,#REF!,1,0),"")<>"",1,"") | AX9: =IF(IFERROR(VLOOKUP(AE9,#REF!,1,0),"")<>"",1,"") | AY9: =IF(IFERROR(VLOOKUP(AE9,#REF!,1,0),"")<>"",1,"") | AZ9: =IF(IFERROR(VLOOKUP(AE9,#REF!,1,0),"")<>"",1,"") | BA9: =IF(IFERROR(VLOOKUP(AE9,#REF!,1,0),"")<>"",1,"") | BB9: =IF(IFERROR(VLOOKUP(AE9,#REF!,1,0),"")<>"",1,"") | BC9: =IF(IFERROR(VLOOKUP(AE9,#REF!,1,0),"")<>"",1,"") | BD9: =IF(IFERROR(VLOOKUP(AE9,#REF!,1,0),"")<>"",1,"") | BE9: =SUM(AR9:BD9) -> 1
A10: 8 | B10: 691114 | C10: =LEFT(B10 & "000000000", 9) -> 691114000 | D10: =MID(C10,1,2) -> 69 | E10: =MID(C10,3,1) -> 1 | F10: =MID(C10,4,1) -> 1 | G10: =MID(C10,5,1) -> 1 | H10: =MID(C10,6,1) -> 4 | I10: =MID(C10,7,1) -> 0 | J10: =MID(C10,8,1) -> 0 | K10: =MID(C10,9,1) -> 0 | L10: J9FA11150000 | M10: 陸稲もちもみ | N10: J9F | O10: A | P10: 農産食品 | Q10: 1 | R10: 1 | S10: もみ | T10: もみ | U10: 1 | V10: 5 | W10: 陸稲もちもみ | X10: 陸稲もちもみ | Y10: 0 | Z10: 0 | AA10: 陸稲もちもみ | AB10: 陸稲もちもみ | AC10: 0 | AD10: 0 | AE10: 陸稲もちもみ | AF10: 陸稲もちもみ | AH10: 1 | AJ10: =IF(OR(AS10=1,AT10=1,AU10=1,AV10=1,AW10=1,AX10=1,AY10=1,AZ10=1,BA10=1,BB10=1,BC10=1,BD10=1),TRUE,FALSE) -> FALSE | AK10: =O10&Q10&R10&U10&V10&Y10&Z10&AC10&AD10 -> A11150000 | AL10: 691114 | AM10: =C10<>AK10 -> TRUE | AN10: =N10&AK10 -> J9FA11150000 | AR10: =IF(AL10<>"",1,"") -> 1 | AS10: =IF(IFERROR(VLOOKUP(AE10,#REF!,1,0),"")<>"",1,"") | AT10: =IF(IFERROR(VLOOKUP(AE10,#REF!,1,0),"")<>"",1,"") | AU10: =IF(IFERROR(VLOOKUP(AE10,#REF!,1,0),"")<>"",1,"") | AV10: =IF(IFERROR(VLOOKUP(AE10,#REF!,1,0),"")<>"",1,"") | AW10: =IF(IFERROR(VLOOKUP(AE10,#REF!,1,0),"")<>"",1,"") | AX10: =IF(IFERROR(VLOOKUP(AE10,#REF!,1,0),"")<>"",1,"") | AY10: =IF(IFERROR(VLOOKUP(AE10,#REF!,1,0),"")<>"",1,"") | AZ10: =IF(IFERROR(VLOOKUP(AE10,#REF!,1,0),"")<>"",1,"") | BA10: =IF(IFERROR(VLOOKUP(AE10,#REF!,1,0),"")<>"",1,"") | BB10: =IF(IFERROR(VLOOKUP(AE10,#REF!,1,0),"")<>"",1,"") | BC10: =IF(IFERROR(VLOOKUP(AE10,#REF!,1,0),"")<>"",1,"") | BD10: =IF(IFERROR(VLOOKUP(AE10,#REF!,1,0),"")<>"",1,"") | BE10: =SUM(AR10:BD10) -> 1
A11: 9 | B11: 69112 | C11: =LEFT(B11 & "000000000", 9) -> 691120000 | D11: =MID(C11,1,2) -> 69 | E11: =MID(C11,3,1) -> 1 | F11: =MID(C11,4,1) -> 1 | G11: =MID(C11,5,1) -> 2 | H11: =MID(C11,6,1) -> 0 | I11: =MID(C11,7,1) -> 0 | J11: =MID(C11,8,1) -> 0 | K11: =MID(C11,9,1) -> 0 | L11: J9FA11160000 | M11: 外国産普通もみ | N11: J9F | O11: A | P11: 農産食品 | Q11: 1 | R11: 1 | S11: もみ | T11: もみ | U11: 1 | V11: 6 | W11: 外国産普通もみ | X11: 外国産普通もみ | Y11: 0 | Z11: 0 | AA11: 外国産普通もみ | AB11: 外国産普通もみ | AC11: 0 | AD11: 0 | AE11: 外国産普通もみ | AF11: 外国産普通もみ | AH11: 1 | AJ11: =IF(OR(AS11=1,AT11=1,AU11=1,AV11=1,AW11=1,AX11=1,AY11=1,AZ11=1,BA11=1,BB11=1,BC11=1,BD11=1),TRUE,FALSE) -> FALSE | AK11: =O11&Q11&R11&U11&V11&Y11&Z11&AC11&AD11 -> A11160000 | AL11: 69112 | AM11: =C11<>AK11 -> TRUE | AN11: =N11&AK11 -> J9FA11160000 | AR11: =IF(AL11<>"",1,"") -> 1 | AS11: =IF(IFERROR(VLOOKUP(AE11,#REF!,1,0),"")<>"",1,"") | AT11: =IF(IFERROR(VLOOKUP(AE11,#REF!,1,0),"")<>"",1,"") | AU11: =IF(IFERROR(VLOOKUP(AE11,#REF!,1,0),"")<>"",1,"") | AV11: =IF(IFERROR(VLOOKUP(AE11,#REF!,1,0),"")<>"",1,"") | AW11: =IF(IFERROR(VLOOKUP(AE11,#REF!,1,0),"")<>"",1,"") | AX11: =IF(IFERROR(VLOOKUP(AE11,#REF!,1,0),"")<>"",1,"") | AY11: =IF(IFERROR(VLOOKUP(AE11,#REF!,1,0),"")<>"",1,"") | AZ11: =IF(IFERROR(VLOOKUP(AE11,#REF!,1,0),"")<>"",1,"") | BA11: =IF(IFERROR(VLOOKUP(AE11,#REF!,1,0),"")<>"",1,"") | BB11: =IF(IFERROR(VLOOKUP(AE11,#REF!,1,0),"")<>"",1,"") | BC11: =IF(IFERROR(VLOOKUP(AE11,#REF!,1,0),"")<>"",1,"") | BD11: =IF(IFERROR(VLOOKUP(AE11,#REF!,1,0),"")<>"",1,"") | BE11: =SUM(AR11:BD11) -> 1
A12: 10 | B12: 691121 | C12: =LEFT(B12 & "000000000", 9) -> 691121000 | D12: =MID(C12,1,2) -> 69 | E12: =MID(C12,3,1) -> 1 | F12: =MID(C12,4,1) -> 1 | G12: =MID(C12,5,1) -> 2 | H12: =MID(C12,6,1) -> 1 | I12: =MID(C12,7,1) -> 0 | J12: =MID(C12,8,1) -> 0 | K12: =MID(C12,9,1) -> 0 | L12: J9FA11170000 | M12: うるちもみ | N12: J9F | O12: A | P12: 農産食品 | Q12: 1 | R12: 1 | S12: もみ | T12: もみ | U12: 1 | V12: 7 | W12: うるちもみ | X12: うるちもみ | Y12: 0 | Z12: 0 | AA12: うるちもみ | AB12: うるちもみ | AC12: 0 | AD12: 0 | AE12: うるちもみ | AF12: うるちもみ | AH12: 1 | AJ12: =IF(OR(AS12=1,AT12=1,AU12=1,AV12=1,AW12=1,AX12=1,AY12=1,AZ12=1,BA12=1,BB12=1,BC12=1,BD12=1),TRUE,FALSE) -> FALSE | AK12: =O12&Q12&R12&U12&V12&Y12&Z12&AC12&AD12 -> A11170000 | AL12: 691121 | AM12: =C12<>AK12 -> TRUE | AN12: =N12&AK12 -> J9FA11170000 | AR12: =IF(AL12<>"",1,"") -> 1 | AS12: =IF(IFERROR(VLOOKUP(AE12,#REF!,1,0),"")<>"",1,"") | AT12: =IF(IFERROR(VLOOKUP(AE12,#REF!,1,0),"")<>"",1,"") | AU12: =IF(IFERROR(VLOOKUP(AE12,#REF!,1,0),"")<>"",1,"") | AV12: =IF(IFERROR(VLOOKUP(AE12,#REF!,1,0),"")<>"",1,"") | AW12: =IF(IFERROR(VLOOKUP(AE12,#REF!,1,0),"")<>"",1,"") | AX12: =IF(IFERROR(VLOOKUP(AE12,#REF!,1,0),"")<>"",1,"") | AY12: =IF(IFERROR(VLOOKUP(AE12,#REF!,1,0),"")<>"",1,"") | AZ12: =IF(IFERROR(VLOOKUP(AE12,#REF!,1,0),"")<>"",1,"") | BA12: =IF(IFERROR(VLOOKUP(AE12,#REF!,1,0),"")<>"",1,"") | BB12: =IF(IFERROR(VLOOKUP(AE12,#REF!,1,0),"")<>"",1,"") | BC12: =IF(IFERROR(VLOOKUP(AE12,#REF!,1,0),"")<>"",1,"") | BD12: =IF(IFERROR(VLOOKUP(AE12,#REF!,1,0),"")<>"",1,"") | BE12: =SUM(AR12:BD12) -> 1
A13: 11 | B13: 691122 | C13: =LEFT(B13 & "000000000", 9) -> 691122000 | D13: =MID(C13,1,2) -> 69 | E13: =MID(C13,3,1) -> 1 | F13: =MID(C13,4,1) -> 1 | G13: =MID(C13,5,1) -> 2 | H13: =MID(C13,6,1) -> 2 | I13: =MID(C13,7,1) -> 0 | J13: =MID(C13,8,1) -> 0 | K13: =MID(C13,9,1) -> 0 | L13: J9FA11180000 | M13: もちもみ | N13: J9F | O13: A | P13: 農産食品 | Q13: 1 | R13: 1 | S13: もみ | T13: もみ | U13: 1 | V13: 8 | W13: もちもみ | X13: もちもみ | Y13: 0 | Z13: 0 | AA13: もちもみ | AB13: もちもみ | AC13: 0 | AD13: 0 | AE13: もちもみ | AF13: もちもみ | AH13: 1 | AJ13: =IF(OR(AS13=1,AT13=1,AU13=1,AV13=1,AW13=1,AX13=1,AY13=1,AZ13=1,BA13=1,BB13=1,BC13=1,BD13=1),TRUE,FALSE) -> FALSE | AK13: =O13&Q13&R13&U13&V13&Y13&Z13&AC13&AD13 -> A11180000 | AL13: 691122 | AM13: =C13<>AK13 -> TRUE | AN13: =N13&AK13 -> J9FA11180000 | AR13: =IF(AL13<>"",1,"") -> 1 | AS13: =IF(IFERROR(VLOOKUP(AE13,#REF!,1,0),"")<>"",1,"") | AT13: =IF(IFERROR(VLOOKUP(AE13,#REF!,1,0),"")<>"",1,"") | AU13: =IF(IFERROR(VLOOKUP(AE13,#REF!,1,0),"")<>"",1,"") | AV13: =IF(IFERROR(VLOOKUP(AE13,#REF!,1,0),"")<>"",1,"") | AW13: =IF(IFERROR(VLOOKUP(AE13,#REF!,1,0),"")<>"",1,"") | AX13: =IF(IFERROR(VLOOKUP(AE13,#REF!,1,0),"")<>"",1,"") | AY13: =IF(IFERROR(VLOOKUP(AE13,#REF!,1,0),"")<>"",1,"") | AZ13: =IF(IFERROR(VLOOKUP(AE13,#REF!,1,0),"")<>"",1,"") | BA13: =IF(IFERROR(VLOOKUP(AE13,#REF!,1,0),"")<>"",1,"") | BB13: =IF(IFERROR(VLOOKUP(AE13,#REF!,1,0),"")<>"",1,"") | BC13: =IF(IFERROR(VLOOKUP(AE13,#REF!,1,0),"")<>"",1,"") | BD13: =IF(IFERROR(VLOOKUP(AE13,#REF!,1,0),"")<>"",1,"") | BE13: =SUM(AR13:BD13) -> 1
L14: J9FA11980000 | M14: もみ（その他） | N14: J9F | O14: A | P14: 農産食品 | Q14: 1 | R14: 1 | S14: もみ | T14: もみ | U14: 9 | V14: 8 | W14: もみ（その他） | X14: もみ（その他） | Y14: 0 | Z14: 0 | AA14: もみ（その他） | AB14: もみ（その他） | AC14: 0 | AD14: 0 | AE14: もみ（その他） | AF14: もみ（その他） | AJ14: =IF(OR(AS14=1,AT14=1,AU14=1,AV14=1,AW14=1,AX14=1,AY14=1,AZ14=1,BA14=1,BB14=1,BC14=1,BD14=1),TRUE,FALSE) -> FALSE | AK14: =O14&Q14&R14&U14&V14&Y14&Z14&AC14&AD14 -> A11980000 | AN14: =N14&AK14 -> J9FA11980000 | BE14: =SUM(AR14:BD14) -> 0
L15: J9FA11990000 | M15: もみ（詳細不明） | N15: J9F | O15: A | P15: 農産食品 | Q15: 1 | R15: 1 | S15: もみ | T15: もみ | U15: 9 | V15: 9 | W15: もみ（詳細不明） | X15: もみ（詳細不明） | Y15: 0 | Z15: 0 | AA15: もみ（詳細不明） | AB15: もみ（詳細不明） | AC15: 0 | AD15: 0 | AE15: もみ（詳細不明） | AF15: もみ（詳細不明） | AJ15: =IF(OR(AS15=1,AT15=1,AU15=1,AV15=1,AW15=1,AX15=1,AY15=1,AZ15=1,BA15=1,BB15=1,BC15=1,BD15=1),TRUE,FALSE) -> FALSE | AK15: =O15&Q15&R15&U15&V15&Y15&Z15&AC15&AD15 -> A11990000 | AN15: =N15&AK15 -> J9FA11990000 | BE15: =SUM(AR15:BD15) -> 0
A16: 12 | B16: 6912 | C16: =LEFT(B16 & "000000000", 9) -> 691200000 | D16: =MID(C16,1,2) -> 69 | E16: =MID(C16,3,1) -> 1 | F16: =MID(C16,4,1) -> 2 | G16: =MID(C16,5,1) -> 0 | H16: =MID(C16,6,1) -> 0 | I16: =MID(C16,7,1) -> 0 | J16: =MID(C16,8,1) -> 0 | K16: =MID(C16,9,1) -> 0 | L16: J9FA12000000 | M16: 玄米 | N16: J9F | O16: A | P16: 農産食品 | Q16: 1 | R16: 2 | S16: 玄米 | T16: 玄米 | U16: 0 | V16: 0 | W16: 玄米 | X16: 玄米 | Y16: 0 | Z16: 0 | AA16: 玄米 | AB16: 玄米 | AC16: 0 | AD16: 0 | AE16: 玄米 | AF16: 玄米 | AJ16: =IF(OR(AS16=1,AT16=1,AU16=1,AV16=1,AW16=1,AX16=1,AY16=1,AZ16=1,BA16=1,BB16=1,BC16=1,BD16=1),TRUE,FALSE) -> FALSE | AK16: =O16&Q16&R16&U16&V16&Y16&Z16&AC16&AD16 -> A12000000 | AL16: 6912 | AM16: =C16<>AK16 -> TRUE | AN16: =N16&AK16 -> J9FA12000000 | AO16: うるち玄米、もち玄米 | AR16: =IF(AL16<>"",1,"") -> 1 | AS16: =IF(IFERROR(VLOOKUP(AE16,#REF!,1,0),"")<>"",1,"") | AT16: =IF(IFERROR(VLOOKUP(AE16,#REF!,1,0),"")<>"",1,"") | AU16: =IF(IFERROR(VLOOKUP(AE16,#REF!,1,0),"")<>"",1,"") | AV16: =IF(IFERROR(VLOOKUP(AE16,#REF!,1,0),"")<>"",1,"") | AW16: =IF(IFERROR(VLOOKUP(AE16,#REF!,1,0),"")<>"",1,"") | AX16: =IF(IFERROR(VLOOKUP(AE16,#REF!,1,0),"")<>"",1,"") | AY16: =IF(IFERROR(VLOOKUP(AE16,#REF!,1,0),"")<>"",1,"") | AZ16: =IF(IFERROR(VLOOKUP(AE16,#REF!,1,0),"")<>"",1,"") | BA16: =IF(IFERROR(VLOOKUP(AE16,#REF!,1,0),"")<>"",1,"") | BB16: =IF(IFERROR(VLOOKUP(AE16,#REF!,1,0),"")<>"",1,"") | BC16: =IF(IFERROR(VLOOKUP(AE16,#REF!,1,0),"")<>"",1,"") | BD16: =IF(IFERROR(VLOOKUP(AE16,#REF!,1,0),"")<>"",1,"") | BE16: =SUM(AR16:BD16) -> 1
A17: 2652 | B17: 999999999 | C17: 999999999 | D17: =MID(C17,1,2) -> 99 | E17: =MID(C17,3,1) -> 9 | F17: =MID(C17,4,1) -> 9 | G17: =MID(C17,5,1) -> 9 | H17: =MID(C17,6,1) -> 9 | I17: =MID(C17,7,1) -> 9 | J17: =MID(C17,8,1) -> 9 | K17: =MID(C17,9,1) -> 9 | L17: J9FA12000011 | M17: 米ぬか | N17: J9F | O17: A | P17: 農産食品 | Q17: 1 | R17: 2 | S17: 玄米 | T17: 玄米 | U17: 0 | V17: 0 | W17: 玄米 | X17: 玄米 | Y17: 0 | Z17: 0 | AA17: 玄米 | AB17: 玄米 | AC17: 1 | AD17: 1 | AE17: 米ぬか | AF17: 米ぬか | AI17: 玄米以下に移動 | AJ17: =IF(OR(AS17=1,AT17=1,AU17=1),TRUE,FALSE) -> FALSE | AK17: =O17&Q17&R17&U17&V17&Y17&Z17&AC17&AD17 -> A12000011 | AM17: =C17<>AK17 -> TRUE | AN17: =N17&AK17 -> J9FA12000011 | AR17: =IF(AL17<>"",1,"") | AS17: =IF(IFERROR(VLOOKUP(AE17,#REF!,1,0),"")<>"",1,"") | AT17: =IF(IFERROR(VLOOKUP(AE17,#REF!,1,0),"")<>"",1,"") | AU17: =IF(IFERROR(VLOOKUP(AE17,#REF!,1,0),"")<>"",1,"") | AV17: =IF(IFERROR(VLOOKUP(AE17,#REF!,1,0),"")<>"",1,"") | AW17: =IF(IFERROR(VLOOKUP(AE17,#REF!,1,0),"")<>"",1,"") | AX17: =IF(IFERROR(VLOOKUP(AE17,#REF!,1,0),"")<>"",1,"") | AY17: =IF(IFERROR(VLOOKUP(AE17,#REF!,1,0),"")<>"",1,"") | AZ17: =IF(IFERROR(VLOOKUP(AE17,#REF!,1,0),"")<>"",1,"") | BA17: =IF(IFERROR(VLOOKUP(AE17,#REF!,1,0),"")<>"",1,"") | BB17: =IF(IFERROR(VLOOKUP(AE17,#REF!,1,0),"")<>"",1,"") | BC17: =IF(IFERROR(VLOOKUP(AE17,#REF!,1,0),"")<>"",1,"") | BD17: =IF(IFERROR(VLOOKUP(AE17,#REF!,1,0),"")<>"",1,"") | BE17: =SUM(AR17:BD17) -> 0
A18: 22 | B18: 69123 | C18: =LEFT(B18 & "000000000", 9) -> 691230000 | D18: =MID(C18,1,2) -> 69 | E18: =MID(C18,3,1) -> 1 | F18: =MID(C18,4,1) -> 2 | G18: =MID(C18,5,1) -> 3 | H18: =MID(C18,6,1) -> 0 | I18: =MID(C18,7,1) -> 0 | J18: =MID(C18,8,1) -> 0 | K18: =MID(C18,9,1) -> 0 | L18: J9FA12000012 | M18: くず玄米 | N18: J9F | O18: A | P18: 農産食品 | Q18: 1 | R18: 2 | S18: 玄米 | T18: 玄米 | U18: 0 | V18: 0 | W18: 玄米 | X18: 玄米 | Y18: 0 | Z18: 0 | AA18: 玄米 | AB18: 玄米 | AC18: 1 | AD18: 2 | AE18: くず玄米 | AF18: くず玄米 | AH18: 1 | AJ18: =IF(OR(AS18=1,AT18=1,AU18=1,AV18=1,AW18=1,AX18=1,AY18=1,AZ18=1,BA18=1,BB18=1,BC18=1,BD18=1),TRUE,FALSE) -> FALSE | AK18: =O18&Q18&R18&U18&V18&Y18&Z18&AC18&AD18 -> A12000012 | AL18: 69123 | AM18: =C18<>AK18 -> TRUE | AN18: =N18&AK18 -> J9FA12000012 | AR18: =IF(AL18<>"",1,"") -> 1 | AS18: =IF(IFERROR(VLOOKUP(AE18,#REF!,1,0),"")<>"",1,"") | AT18: =IF(IFERROR(VLOOKUP(AE18,#REF!,1,0),"")<>"",1,"") | AU18: =IF(IFERROR(VLOOKUP(AE18,#REF!,1,0),"")<>"",1,"") | AV18: =IF(IFERROR(VLOOKUP(AE18,#REF!,1,0),"")<>"",1,"") | AW18: =IF(IFERROR(VLOOKUP(AE18,#REF!,1,0),"")<>"",1,"") | AX18: =IF(IFERROR(VLOOKUP(AE18,#REF!,1,0),"")<>"",1,"") | AY18: =IF(IFERROR(VLOOKUP(AE18,#REF!,1,0),"")<>"",1,"") | AZ18: =IF(IFERROR(VLOOKUP(AE18,#REF!,1,0),"")<>"",1,"") | BA18: =IF(IFERROR(VLOOKUP(AE18,#REF!,1,0),"")<>"",1,"") | BB18: =IF(IFERROR(VLOOKUP(AE18,#REF!,1,0),"")<>"",1,"") | BC18: =IF(IFERROR(VLOOKUP(AE18,#REF!,1,0),"")<>"",1,"") | BD18: =IF(IFERROR(VLOOKUP(AE18,#REF!,1,0),"")<>"",1,"") | BE18: =SUM(AR18:BD18) -> 1
A19: 13 | B19: 69121 | C19: =LEFT(B19 & "000000000", 9) -> 691210000 | D19: =MID(C19,1,2) -> 69 | E19: =MID(C19,3,1) -> 1 | F19: =MID(C19,4,1) -> 2 | G19: =MID(C19,5,1) -> 1 | H19: =MID(C19,6,1) -> 0 | I19: =MID(C19,7,1) -> 0 | J19: =MID(C19,8,1) -> 0 | K19: =MID(C19,9,1) -> 0 | L19: J9FA12110000 | M19: 国内産玄米 | N19: J9F | O19: A | P19: 農産食品 | Q19: 1 | R19: 2 | S19: 玄米 | T19: 玄米 | U19: 1 | V19: 1 | W19: 国内産玄米 | X19: 国内産玄米 | Y19: 0 | Z19: 0 | AA19: 国内産玄米 | AB19: 国内産玄米 | AC19: 0 | AD19: 0 | AE19: 国内産玄米 | AF19: 国内産玄米 | AH19: 1 | AJ19: =IF(OR(AS19=1,AT19=1,AU19=1,AV19=1,AW19=1,AX19=1,AY19=1,AZ19=1,BA19=1,BB19=1,BC19=1,BD19=1),TRUE,FALSE) -> FALSE | AK19: =O19&Q19&R19&U19&V19&Y19&Z19&AC19&AD19 -> A12110000 | AL19: 69121 | AM19: =C19<>AK19 -> TRUE | AN19: =N19&AK19 -> J9FA12110000 | AR19: =IF(AL19<>"",1,"") -> 1 | AS19: =IF(IFERROR(VLOOKUP(AE19,#REF!,1,0),"")<>"",1,"") | AT19: =IF(IFERROR(VLOOKUP(AE19,#REF!,1,0),"")<>"",1,"") | AU19: =IF(IFERROR(VLOOKUP(AE19,#REF!,1,0),"")<>"",1,"") | AV19: =IF(IFERROR(VLOOKUP(AE19,#REF!,1,0),"")<>"",1,"") | AW19: =IF(IFERROR(VLOOKUP(AE19,#REF!,1,0),"")<>"",1,"") | AX19: =IF(IFERROR(VLOOKUP(AE19,#REF!,1,0),"")<>"",1,"") | AY19: =IF(IFERROR(VLOOKUP(AE19,#REF!,1,0),"")<>"",1,"") | AZ19: =IF(IFERROR(VLOOKUP(AE19,#REF!,1,0),"")<>"",1,"") | BA19: =IF(IFERROR(VLOOKUP(AE19,#REF!,1,0),"")<>"",1,"") | BB19: =IF(IFERROR(VLOOKUP(AE19,#REF!,1,0),"")<>"",1,"") | BC19: =IF(IFERROR(VLOOKUP(AE19,#REF!,1,0),"")<>"",1,"") | BD19: =IF(IFERROR(VLOOKUP(AE19,#REF!,1,0),"")<>"",1,"") | BE19: =SUM(AR19:BD19) -> 1
A20: 14 | B20: 691211 | C20: =LEFT(B20 & "000000000", 9) -> 691211000 | D20: =MID(C20,1,2) -> 69 | E20: =MID(C20,3,1) -> 1 | F20: =MID(C20,4,1) -> 2 | G20: =MID(C20,5,1) -> 1 | H20: =MID(C20,6,1) -> 1 | I20: =MID(C20,7,1) -> 0 | J20: =MID(C20,8,1) -> 0 | K20: =MID(C20,9,1) -> 0 | L20: J9FA12120000 | M20: 水稲うるち玄米 | N20: J9F | O20: A | P20: 農産食品 | Q20: 1 | R20: 2 | S20: 玄米 | T20: 玄米 | U20: 1 | V20: 2 | W20: 水稲うるち玄米 | X20: 水稲うるち玄米 | Y20: 0 | Z20: 0 | AA20: 水稲うるち玄米 | AB20: 水稲うるち玄米 | AC20: 0 | AD20: 0 | AE20: 水稲うるち玄米 | AF20: 水稲うるち玄米 | AH20: 1 | AJ20: =IF(OR(AS20=1,AT20=1,AU20=1,AV20=1,AW20=1,AX20=1,AY20=1,AZ20=1,BA20=1,BB20=1,BC20=1,BD20=1),TRUE,FALSE) -> FALSE | AK20: =O20&Q20&R20&U20&V20&Y20&Z20&AC20&AD20 -> A12120000 | AL20: 691211 | AM20: =C20<>AK20 -> TRUE | AN20: =N20&AK20 -> J9FA12120000 | AR20: =IF(AL20<>"",1,"") -> 1 | AS20: =IF(IFERROR(VLOOKUP(AE20,#REF!,1,0),"")<>"",1,"") | AT20: =IF(IFERROR(VLOOKUP(AE20,#REF!,1,0),"")<>"",1,"") | AU20: =IF(IFERROR(VLOOKUP(AE20,#REF!,1,0),"")<>"",1,"") | AV20: =IF(IFERROR(VLOOKUP(AE20,#REF!,1,0),"")<>"",1,"") | AW20: =IF(IFERROR(VLOOKUP(AE20,#REF!,1,0),"")<>"",1,"") | AX20: =IF(IFERROR(VLOOKUP(AE20,#REF!,1,0),"")<>"",1,"") | AY20: =IF(IFERROR(VLOOKUP(AE20,#REF!,1,0),"")<>"",1,"") | AZ20: =IF(IFERROR(VLOOKUP(AE20,#REF!,1,0),"")<>"",1,"") | BA20: =IF(IFERROR(VLOOKUP(AE20,#REF!,1,0),"")<>"",1,"") | BB20: =IF(IFERROR(VLOOKUP(AE20,#REF!,1,0),"")<>"",1,"") | BC20: =IF(IFERROR(VLOOKUP(AE20,#REF!,1,0),"")<>"",1,"") | BD20: =IF(IFERROR(VLOOKUP(AE20,#REF!,1,0),"")<>"",1,"") | BE20: =SUM(AR20:BD20) -> 1
A21: 15 | B21: 691212 | C21: =LEFT(B21 & "000000000", 9) -> 691212000 | D21: =MID(C21,1,2) -> 69 | E21: =MID(C21,3,1) -> 1 | F21: =MID(C21,4,1) -> 2 | G21: =MID(C21,5,1) -> 1 | H21: =MID(C21,6,1) -> 2 | I21: =MID(C21,7,1) -> 0 | J21: =MID(C21,8,1) -> 0 | K21: =MID(C21,9,1) -> 0 | L21: J9FA12130000 | M21: 水稲もち玄米 | N21: J9F | O21: A | P21: 農産食品 | Q21: 1 | R21: 2 | S21: 玄米 | T21: 玄米 | U21: 1 | V21: 3 | W21: 水稲もち玄米 | X21: 水稲もち玄米 | Y21: 0 | Z21: 0 | AA21: 水稲もち玄米 | AB21: 水稲もち玄米 | AC21: 0 | AD21: 0 | AE21: 水稲もち玄米 | AF21: 水稲もち玄米 | AH21: 1 | AJ21: =IF(OR(AS21=1,AT21=1,AU21=1,AV21=1,AW21=1,AX21=1,AY21=1,AZ21=1,BA21=1,BB21=1,BC21=1,BD21=1),TRUE,FALSE) -> FALSE | AK21: =O21&Q21&R21&U21&V21&Y21&Z21&AC21&AD21 -> A12130000 | AL21: 691212 | AM21: =C21<>AK21 -> TRUE | AN21: =N21&AK21 -> J9FA12130000 | AR21: =IF(AL21<>"",1,"") -> 1 | AS21: =IF(IFERROR(VLOOKUP(AE21,#REF!,1,0),"")<>"",1,"") | AT21: =IF(IFERROR(VLOOKUP(AE21,#REF!,1,0),"")<>"",1,"") | AU21: =IF(IFERROR(VLOOKUP(AE21,#REF!,1,0),"")<>"",1,"") | AV21: =IF(IFERROR(VLOOKUP(AE21,#REF!,1,0),"")<>"",1,"") | AW21: =IF(IFERROR(VLOOKUP(AE21,#REF!,1,0),"")<>"",1,"") | AX21: =IF(IFERROR(VLOOKUP(AE21,#REF!,1,0),"")<>"",1,"") | AY21: =IF(IFERROR(VLOOKUP(AE21,#REF!,1,0),"")<>"",1,"") | AZ21: =IF(IFERROR(VLOOKUP(AE21,#REF!,1,0),"")<>"",1,"") | BA21: =IF(IFERROR(VLOOKUP(AE21,#REF!,1,0),"")<>"",1,"") | BB21: =IF(IFERROR(VLOOKUP(AE21,#REF!,1,0),"")<>"",1,"") | BC21: =IF(IFERROR(VLOOKUP(AE21,#REF!,1,0),"")<>"",1,"") | BD21: =IF(IFERROR(VLOOKUP(AE21,#REF!,1,0),"")<>"",1,"") | BE21: =SUM(AR21:BD21) -> 1
A22: 16 | B22: 691213 | C22: =LEFT(B22 & "000000000", 9) -> 691213000 | D22: =MID(C22,1,2) -> 69 | E22: =MID(C22,3,1) -> 1 | F22: =MID(C22,4,1) -> 2 | G22: =MID(C22,5,1) -> 1 | H22: =MID(C22,6,1) -> 3 | I22: =MID(C22,7,1) -> 0 | J22: =MID(C22,8,1) -> 0 | K22: =MID(C22,9,1) -> 0 | L22: J9FA12140000 | M22: 陸稲うるち玄米 | N22: J9F | O22: A | P22: 農産食品 | Q22: 1 | R22: 2 | S22: 玄米 | T22: 玄米 | U22: 1 | V22: 4 | W22: 陸稲うるち玄米 | X22: 陸稲うるち玄米 | Y22: 0 | Z22: 0 | AA22: 陸稲うるち玄米 | AB22: 陸稲うるち玄米 | AC22: 0 | AD22: 0 | AE22: 陸稲うるち玄米 | AF22: 陸稲うるち玄米 | AH22: 1 | AJ22: =IF(OR(AS22=1,AT22=1,AU22=1,AV22=1,AW22=1,AX22=1,AY22=1,AZ22=1,BA22=1,BB22=1,BC22=1,BD22=1),TRUE,FALSE) -> FALSE | AK22: =O22&Q22&R22&U22&V22&Y22&Z22&AC22&AD22 -> A12140000 | AL22: 691213 | AM22: =C22<>AK22 -> TRUE | AN22: =N22&AK22 -> J9FA12140000 | AR22: =IF(AL22<>"",1,"") -> 1 | AS22: =IF(IFERROR(VLOOKUP(AE22,#REF!,1,0),"")<>"",1,"") | AT22: =IF(IFERROR(VLOOKUP(AE22,#REF!,1,0),"")<>"",1,"") | AU22: =IF(IFERROR(VLOOKUP(AE22,#REF!,1,0),"")<>"",1,"") | AV22: =IF(IFERROR(VLOOKUP(AE22,#REF!,1,0),"")<>"",1,"") | AW22: =IF(IFERROR(VLOOKUP(AE22,#REF!,1,0),"")<>"",1,"") | AX22: =IF(IFERROR(VLOOKUP(AE22,#REF!,1,0),"")<>"",1,"") | AY22: =IF(IFERROR(VLOOKUP(AE22,#REF!,1,0),"")<>"",1,"") | AZ22: =IF(IFERROR(VLOOKUP(AE22,#REF!,1,0),"")<>"",1,"") | BA22: =IF(IFERROR(VLOOKUP(AE22,#REF!,1,0),"")<>"",1,"") | BB22: =IF(IFERROR(VLOOKUP(AE22,#REF!,1,0),"")<>"",1,"") | BC22: =IF(IFERROR(VLOOKUP(AE22,#REF!,1,0),"")<>"",1,"") | BD22: =IF(IFERROR(VLOOKUP(AE22,#REF!,1,0),"")<>"",1,"") | BE22: =SUM(AR22:BD22) -> 1
A23: 17 | B23: 691214 | C23: =LEFT(B23 & "000000000", 9) -> 691214000 | D23: =MID(C23,1,2) -> 69 | E23: =MID(C23,3,1) -> 1 | F23: =MID(C23,4,1) -> 2 | G23: =MID(C23,5,1) -> 1 | H23: =MID(C23,6,1) -> 4 | I23: =MID(C23,7,1) -> 0 | J23: =MID(C23,8,1) -> 0 | K23: =MID(C23,9,1) -> 0 | L23: J9FA12150000 | M23: 陸稲もち玄米 | N23: J9F | O23: A | P23: 農産食品 | Q23: 1 | R23: 2 | S23: 玄米 | T23: 玄米 | U23: 1 | V23: 5 | W23: 陸稲もち玄米 | X23: 陸稲もち玄米 | Y23: 0 | Z23: 0 | AA23: 陸稲もち玄米 | AB23: 陸稲もち玄米 | AC23: 0 | AD23: 0 | AE23: 陸稲もち玄米 | AF23: 陸稲もち玄米 | AH23: 1 | AJ23: =IF(OR(AS23=1,AT23=1,AU23=1,AV23=1,AW23=1,AX23=1,AY23=1,AZ23=1,BA23=1,BB23=1,BC23=1,BD23=1),TRUE,FALSE) -> FALSE | AK23: =O23&Q23&R23&U23&V23&Y23&Z23&AC23&AD23 -> A12150000 | AL23: 691214 | AM23: =C23<>AK23 -> TRUE | AN23: =N23&AK23 -> J9FA12150000 | AR23: =IF(AL23<>"",1,"") -> 1 | AS23: =IF(IFERROR(VLOOKUP(AE23,#REF!,1,0),"")<>"",1,"") | AT23: =IF(IFERROR(VLOOKUP(AE23,#REF!,1,0),"")<>"",1,"") | AU23: =IF(IFERROR(VLOOKUP(AE23,#REF!,1,0),"")<>"",1,"") | AV23: =IF(IFERROR(VLOOKUP(AE23,#REF!,1,0),"")<>"",1,"") | AW23: =IF(IFERROR(VLOOKUP(AE23,#REF!,1,0),"")<>"",1,"") | AX23: =IF(IFERROR(VLOOKUP(AE23,#REF!,1,0),"")<>"",1,"") | AY23: =IF(IFERROR(VLOOKUP(AE23,#REF!,1,0),"")<>"",1,"") | AZ23: =IF(IFERROR(VLOOKUP(AE23,#REF!,1,0),"")<>"",1,"") | BA23: =IF(IFERROR(VLOOKUP(AE23,#REF!,1,0),"")<>"",1,"") | BB23: =IF(IFERROR(VLOOKUP(AE23,#REF!,1,0),"")<>"",1,"") | BC23: =IF(IFERROR(VLOOKUP(AE23,#REF!,1,0),"")<>"",1,"") | BD23: =IF(IFERROR(VLOOKUP(AE23,#REF!,1,0),"")<>"",1,"") | BE23: =SUM(AR23:BD23) -> 1
A24: 18 | B24: 691215 | C24: =LEFT(B24 & "000000000", 9) -> 691215000 | D24: =MID(C24,1,2) -> 69 | E24: =MID(C24,3,1) -> 1 | F24: =MID(C24,4,1) -> 2 | G24: =MID(C24,5,1) -> 1 | H24: =MID(C24,6,1) -> 5 | I24: =MID(C24,7,1) -> 0 | J24: =MID(C24,8,1) -> 0 | K24: =MID(C24,9,1) -> 0 | L24: J9FA12160000 | M24: 醸造用玄米 | N24: J9F | O24: A | P24: 農産食品 | Q24: 1 | R24: 2 | S24: 玄米 | T24: 玄米 | U24: 1 | V24: 6 | W24: 醸造用玄米 | X24: 醸造用玄米 | Y24: 0 | Z24: 0 | AA24: 醸造用玄米 | AB24: 醸造用玄米 | AC24: 0 | AD24: 0 | AE24: 醸造用玄米 | AF24: 醸造用玄米 | AH24: 1 | AJ24: =IF(OR(AS24=1,AT24=1,AU24=1,AV24=1,AW24=1,AX24=1,AY24=1,AZ24=1,BA24=1,BB24=1,BC24=1,BD24=1),TRUE,FALSE) -> FALSE | AK24: =O24&Q24&R24&U24&V24&Y24&Z24&AC24&AD24 -> A12160000 | AL24: 691215 | AM24: =C24<>AK24 -> TRUE | AN24: =N24&AK24 -> J9FA12160000 | AR24: =IF(AL24<>"",1,"") -> 1 | AS24: =IF(IFERROR(VLOOKUP(AE24,#REF!,1,0),"")<>"",1,"") | AT24: =IF(IFERROR(VLOOKUP(AE24,#REF!,1,0),"")<>"",1,"") | AU24: =IF(IFERROR(VLOOKUP(AE24,#REF!,1,0),"")<>"",1,"") | AV24: =IF(IFERROR(VLOOKUP(AE24,#REF!,1,0),"")<>"",1,"") | AW24: =IF(IFERROR(VLOOKUP(AE24,#REF!,1,0),"")<>"",1,"") | AX24: =IF(IFERROR(VLOOKUP(AE24,#REF!,1,0),"")<>"",1,"") | AY24: =IF(IFERROR(VLOOKUP(AE24,#REF!,1,0),"")<>"",1,"") | AZ24: =IF(IFERROR(VLOOKUP(AE24,#REF!,1,0),"")<>"",1,"") | BA24: =IF(IFERROR(VLOOKUP(AE24,#REF!,1,0),"")<>"",1,"") | BB24: =IF(IFERROR(VLOOKUP(AE24,#REF!,1,0),"")<>"",1,"") | BC24: =IF(IFERROR(VLOOKUP(AE24,#REF!,1,0),"")<>"",1,"") | BD24: =IF(IFERROR(VLOOKUP(AE24,#REF!,1,0),"")<>"",1,"") | BE24: =SUM(AR24:BD24) -> 1
A25: 19 | B25: 69122 | C25: =LEFT(B25 & "000000000", 9) -> 691220000 | D25: =MID(C25,1,2) -> 69 | E25: =MID(C25,3,1) -> 1 | F25: =MID(C25,4,1) -> 2 | G25: =MID(C25,5,1) -> 2 | H25: =MID(C25,6,1) -> 0 | I25: =MID(C25,7,1) -> 0 | J25: =MID(C25,8,1) -> 0 | K25: =MID(C25,9,1) -> 0 | L25: J9FA12170000 | M25: 外国産玄米 | N25: J9F | O25: A | P25: 農産食品 | Q25: 1 | R25: 2 | S25: 玄米 | T25: 玄米 | U25: 1 | V25: 7 | W25: 外国産玄米 | X25: 外国産玄米 | Y25: 0 | Z25: 0 | AA25: 外国産玄米 | AB25: 外国産玄米 | AC25: 0 | AD25: 0 | AE25: 外国産玄米 | AF25: 外国産玄米 | AH25: 1 | AJ25: =IF(OR(AS25=1,AT25=1,AU25=1,AV25=1,AW25=1,AX25=1,AY25=1,AZ25=1,BA25=1,BB25=1,BC25=1,BD25=1),TRUE,FALSE) -> FALSE | AK25: =O25&Q25&R25&U25&V25&Y25&Z25&AC25&AD25 -> A12170000 | AL25: 69122 | AM25: =C25<>AK25 -> TRUE | AN25: =N25&AK25 -> J9FA12170000 | AR25: =IF(AL25<>"",1,"") -> 1 | AS25: =IF(IFERROR(VLOOKUP(AE25,#REF!,1,0),"")<>"",1,"") | AT25: =IF(IFERROR(VLOOKUP(AE25,#REF!,1,0),"")<>"",1,"") | AU25: =IF(IFERROR(VLOOKUP(AE25,#REF!,1,0),"")<>"",1,"") | AV25: =IF(IFERROR(VLOOKUP(AE25,#REF!,1,0),"")<>"",1,"") | AW25: =IF(IFERROR(VLOOKUP(AE25,#REF!,1,0),"")<>"",1,"") | AX25: =IF(IFERROR(VLOOKUP(AE25,#REF!,1,0),"")<>"",1,"") | AY25: =IF(IFERROR(VLOOKUP(AE25,#REF!,1,0),"")<>"",1,"") | AZ25: =IF(IFERROR(VLOOKUP(AE25,#REF!,1,0),"")<>"",1,"") | BA25: =IF(IFERROR(VLOOKUP(AE25,#REF!,1,0),"")<>"",1,"") | BB25: =IF(IFERROR(VLOOKUP(AE25,#REF!,1,0),"")<>"",1,"") | BC25: =IF(IFERROR(VLOOKUP(AE25,#REF!,1,0),"")<>"",1,"") | BD25: =IF(IFERROR(VLOOKUP(AE25,#REF!,1,0),"")<>"",1,"") | BE25: =SUM(AR25:BD25) -> 1
A26: 20 | B26: 691221 | C26: =LEFT(B26 & "000000000", 9) -> 691221000 | D26: =MID(C26,1,2) -> 69 | E26: =MID(C26,3,1) -> 1 | F26: =MID(C26,4,1) -> 2 | G26: =MID(C26,5,1) -> 2 | H26: =MID(C26,6,1) -> 1 | I26: =MID(C26,7,1) -> 0 | J26: =MID(C26,8,1) -> 0 | K26: =MID(C26,9,1) -> 0 | L26: J9FA12180000 | M26: うるち玄米 | N26: J9F | O26: A | P26: 農産食品 | Q26: 1 | R26: 2 | S26: 玄米 | T26: 玄米 | U26: 1 | V26: 8 | W26: うるち玄米 | X26: うるち玄米 | Y26: 0 | Z26: 0 | AA26: うるち玄米 | AB26: うるち玄米 | AC26: 0 | AD26: 0 | AE26: うるち玄米 | AF26: うるち玄米 | AH26: 1 | AJ26: =IF(OR(AS26=1,AT26=1,AU26=1,AV26=1,AW26=1,AX26=1,AY26=1,AZ26=1,BA26=1,BB26=1,BC26=1,BD26=1),TRUE,FALSE) -> FALSE | AK26: =O26&Q26&R26&U26&V26&Y26&Z26&AC26&AD26 -> A12180000 | AL26: 691221 | AM26: =C26<>AK26 -> TRUE | AN26: =N26&AK26 -> J9FA12180000 | AR26: =IF(AL26<>"",1,"") -> 1 | AS26: =IF(IFERROR(VLOOKUP(AE26,#REF!,1,0),"")<>"",1,"") | AT26: =IF(IFERROR(VLOOKUP(AE26,#REF!,1,0),"")<>"",1,"") | AU26: =IF(IFERROR(VLOOKUP(AE26,#REF!,1,0),"")<>"",1,"") | AV26: =IF(IFERROR(VLOOKUP(AE26,#REF!,1,0),"")<>"",1,"") | AW26: =IF(IFERROR(VLOOKUP(AE26,#REF!,1,0),"")<>"",1,"") | AX26: =IF(IFERROR(VLOOKUP(AE26,#REF!,1,0),"")<>"",1,"") | AY26: =IF(IFERROR(VLOOKUP(AE26,#REF!,1,0),"")<>"",1,"") | AZ26: =IF(IFERROR(VLOOKUP(AE26,#REF!,1,0),"")<>"",1,"") | BA26: =IF(IFERROR(VLOOKUP(AE26,#REF!,1,0),"")<>"",1,"") | BB26: =IF(IFERROR(VLOOKUP(AE26,#REF!,1,0),"")<>"",1,"") | BC26: =IF(IFERROR(VLOOKUP(AE26,#REF!,1,0),"")<>"",1,"") | BD26: =IF(IFERROR(VLOOKUP(AE26,#REF!,1,0),"")<>"",1,"") | BE26: =SUM(AR26:BD26) -> 1
A27: 21 | B27: 691222 | C27: =LEFT(B27 & "000000000", 9) -> 691222000 | D27: =MID(C27,1,2) -> 69 | E27: =MID(C27,3,1) -> 1 | F27: =MID(C27,4,1) -> 2 | G27: =MID(C27,5,1) -> 2 | H27: =MID(C27,6,1) -> 2 | I27: =MID(C27,7,1) -> 0 | J27: =MID(C27,8,1) -> 0 | K27: =MID(C27,9,1) -> 0 | L27: J9FA12190000 | M27: もち玄米 | N27: J9F | O27: A | P27: 農産食品 | Q27: 1 | R27: 2 | S27: 玄米 | T27: 玄米 | U27: 1 | V27: 9 | W27: もち玄米 | X27: もち玄米 | Y27: 0 | Z27: 0 | AA27: もち玄米 | AB27: もち玄米 | AC27: 0 | AD27: 0 | AE27: もち玄米 | AF27: もち玄米 | AH27: 1 | AJ27: =IF(OR(AS27=1,AT27=1,AU27=1,AV27=1,AW27=1,AX27=1,AY27=1,AZ27=1,BA27=1,BB27=1,BC27=1,BD27=1),TRUE,FALSE) -> FALSE | AK27: =O27&Q27&R27&U27&V27&Y27&Z27&AC27&AD27 -> A12190000 | AL27: 691222 | AM27: =C27<>AK27 -> TRUE | AN27: =N27&AK27 -> J9FA12190000 | AR27: =IF(AL27<>"",1,"") -> 1 | AS27: =IF(IFERROR(VLOOKUP(AE27,#REF!,1,0),"")<>"",1,"") | AT27: =IF(IFERROR(VLOOKUP(AE27,#REF!,1,0),"")<>"",1,"") | AU27: =IF(IFERROR(VLOOKUP(AE27,#REF!,1,0),"")<>"",1,"") | AV27: =IF(IFERROR(VLOOKUP(AE27,#REF!,1,0),"")<>"",1,"") | AW27: =IF(IFERROR(VLOOKUP(AE27,#REF!,1,0),"")<>"",1,"") | AX27: =IF(IFERROR(VLOOKUP(AE27,#REF!,1,0),"")<>"",1,"") | AY27: =IF(IFERROR(VLOOKUP(AE27,#REF!,1,0),"")<>"",1,"") | AZ27: =IF(IFERROR(VLOOKUP(AE27,#REF!,1,0),"")<>"",1,"") | BA27: =IF(IFERROR(VLOOKUP(AE27,#REF!,1,0),"")<>"",1,"") | BB27: =IF(IFERROR(VLOOKUP(AE27,#REF!,1,0),"")<>"",1,"") | BC27: =IF(IFERROR(VLOOKUP(AE27,#REF!,1,0),"")<>"",1,"") | BD27: =IF(IFERROR(VLOOKUP(AE27,#REF!,1,0),"")<>"",1,"") | BE27: =SUM(AR27:BD27) -> 1
L28: J9FA12980000 | N28: J9F | O28: A | P28: 農産食品 | Q28: 1 | R28: 2 | S28: 玄米 | T28: 玄米 | U28: 9 | V28: 8 | W28: 玄米（その他） | X28: 玄米（その他） | Y28: 0 | Z28: 0 | AA28: 玄米（その他） | AB28: 玄米（その他） | AC28: 0 | AD28: 0 | AE28: 玄米（その他） | AF28: 玄米（その他） | AJ28: =IF(OR(AS28=1,AT28=1,AU28=1,AV28=1,AW28=1,AX28=1,AY28=1,AZ28=1,BA28=1,BB28=1,BC28=1,BD28=1),TRUE,FALSE) -> FALSE | AK28: =O28&Q28&R28&U28&V28&Y28&Z28&AC28&AD28 -> A12980000 | AN28: =N28&AK28 -> J9FA12980000 | BE28: =SUM(AR28:BD28) -> 0
L29: J9FA12990000 | N29: J9F | O29: A | P29: 農産食品 | Q29: 1 | R29: 2 | S29: 玄米 | T29: 玄米 | U29: 9 | V29: 9 | W29: 玄米（詳細不明） | X29: 玄米（詳細不明） | Y29: 0 | Z29: 0 | AA29: 玄米（詳細不明） | AB29: 玄米（詳細不明） | AC29: 0 | AD29: 0 | AE29: 玄米（詳細不明） | AF29: 玄米（詳細不明） | AJ29: =IF(OR(AS29=1,AT29=1,AU29=1,AV29=1,AW29=1,AX29=1,AY29=1,AZ29=1,BA29=1,BB29=1,BC29=1,BD29=1),TRUE,FALSE) -> FALSE | AK29: =O29&Q29&R29&U29&V29&Y29&Z29&AC29&AD29 -> A12990000 | AN29: =N29&AK29 -> J9FA12990000 | BE29: =SUM(AR29:BD29) -> 0
A30: 23 | B30: 6913 | C30: =LEFT(B30 & "000000000", 9) -> 691300000 | D30: =MID(C30,1,2) -> 69 | E30: =MID(C30,3,1) -> 1 | F30: =MID(C30,4,1) -> 3 | G30: =MID(C30,5,1) -> 0 | H30: =MID(C30,6,1) -> 0 | I30: =MID(C30,7,1) -> 0 | J30: =MID(C30,8,1) -> 0 | K30: =MID(C30,9,1) -> 0 | L30: J9FA13000000 | M30: 精米 | N30: J9F | O30: A | P30: 農産食品 | Q30: 1 | R30: 3 | S30: 精米 | T30: 精米 | U30: 0 | V30: 0 | W30: 精米 | X30: 精米 | Y30: 0 | Z30: 0 | AA30: 精米 | AB30: 精米 | AC30: 0 | AD30: 0 | AE30: 精米 | AF30: 白米 | AI30: 精米のPTを白米に変更 | AJ30: =IF(OR(AS30=1,AT30=1,AU30=1,AV30=1,AW30=1,AX30=1,AY30=1,AZ30=1,BA30=1,BB30=1,BC30=1,BD30=1),TRUE,FALSE) -> FALSE | AK30: =O30&Q30&R30&U30&V30&Y30&Z30&AC30&AD30 -> A13000000 | AL30: 6913 | AM30: =C30<>AK30 -> TRUE | AN30: =N30&AK30 -> J9FA13000000 | AO30: 精米、うるち精米、もち精米 | AR30: =IF(AL30<>"",1,"") -> 1 | AS30: =IF(IFERROR(VLOOKUP(AE30,#REF!,1,0),"")<>"",1,"") | AT30: =IF(IFERROR(VLOOKUP(AE30,#REF!,1,0),"")<>"",1,"") | AU30: =IF(IFERROR(VLOOKUP(AE30,#REF!,1,0),"")<>"",1,"") | AV30: =IF(IFERROR(VLOOKUP(AE30,#REF!,1,0),"")<>"",1,"") | AW30: =IF(IFERROR(VLOOKUP(AE30,#REF!,1,0),"")<>"",1,"") | AX30: =IF(IFERROR(VLOOKUP(AE30,#REF!,1,0),"")<>"",1,"") | AY30: =IF(IFERROR(VLOOKUP(AE30,#REF!,1,0),"")<>"",1,"") | AZ30: =IF(IFERROR(VLOOKUP(AE30,#REF!,1,0),"")<>"",1,"") | BA30: =IF(IFERROR(VLOOKUP(AE30,#REF!,1,0),"")<>"",1,"") | BB30: =IF(IFERROR(VLOOKUP(AE30,#REF!,1,0),"")<>"",1,"") | BC30: =IF(IFERROR(VLOOKUP(AE30,#REF!,1,0),"")<>"",1,"") | BD30: =IF(IFERROR(VLOOKUP(AE30,#REF!,1,0),"")<>"",1,"") | BE30: =SUM(AR30:BD30) -> 1
A31: 32 | B31: 69133 | C31: =LEFT(B31 & "000000000", 9) -> 691330000 | D31: =MID(C31,1,2) -> 69 | E31: =MID(C31,3,1) -> 1 | F31: =MID(C31,4,1) -> 3 | G31: =MID(C31,5,1) -> 3 | H31: =MID(C31,6,1) -> 0 | I31: =MID(C31,7,1) -> 0 | J31: =MID(C31,8,1) -> 0 | K31: =MID(C31,9,1) -> 0 | L31: J9FA13000011 | M31: 砕精米 | N31: J9F | O31: A | P31: 農産食品 | Q31: 1 | R31: 3 | S31: 精米 | T31: 精米 | U31: 0 | V31: 0 | W31: 精米 | X31: 精米 | Y31: 0 | Z31: 0 | AA31: 精米 | AB31: 精米 | AC31: 1 | AD31: 1 | AE31: 砕精米 | AF31: 砕精米 | AH31: 1 | AJ31: =IF(OR(AS31=1,AT31=1,AU31=1,AV31=1,AW31=1,AX31=1,AY31=1,AZ31=1,BA31=1,BB31=1,BC31=1,BD31=1),TRUE,FALSE) -> FALSE | AK31: =O31&Q31&R31&U31&V31&Y31&Z31&AC31&AD31 -> A13000011 | AL31: 69133 | AM31: =C31<>AK31 -> TRUE | AN31: =N31&AK31 -> J9FA13000011 | AR31: =IF(AL31<>"",1,"") -> 1 | AS31: =IF(IFERROR(VLOOKUP(AE31,#REF!,1,0),"")<>"",1,"") | AT31: =IF(IFERROR(VLOOKUP(AE31,#REF!,1,0),"")<>"",1,"") | AU31: =IF(IFERROR(VLOOKUP(AE31,#REF!,1,0),"")<>"",1,"") | AV31: =IF(IFERROR(VLOOKUP(AE31,#REF!,1,0),"")<>"",1,"") | AW31: =IF(IFERROR(VLOOKUP(AE31,#REF!,1,0),"")<>"",1,"") | AX31: =IF(IFERROR(VLOOKUP(AE31,#REF!,1,0),"")<>"",1,"") | AY31: =IF(IFERROR(VLOOKUP(AE31,#REF!,1,0),"")<>"",1,"") | AZ31: =IF(IFERROR(VLOOKUP(AE31,#REF!,1,0),"")<>"",1,"") | BA31: =IF(IFERROR(VLOOKUP(AE31,#REF!,1,0),"")<>"",1,"") | BB31: =IF(IFERROR(VLOOKUP(AE31,#REF!,1,0),"")<>"",1,"") | BC31: =IF(IFERROR(VLOOKUP(AE31,#REF!,1,0),"")<>"",1,"") | BD31: =IF(IFERROR(VLOOKUP(AE31,#REF!,1,0),"")<>"",1,"") | BE31: =SUM(AR31:BD31) -> 1
A32: 1490 | B32: 72622 | C32: =LEFT(B32 & "000000000", 9) -> 726220000 | D32: =MID(C32,1,2) -> 72 | E32: =MID(C32,3,1) -> 6 | F32: =MID(C32,4,1) -> 2 | G32: =MID(C32,5,1) -> 2 | H32: =MID(C32,6,1) -> 0 | I32: =MID(C32,7,1) -> 0 | J32: =MID(C32,8,1) -> 0 | K32: =MID(C32,9,1) -> 0 | L32: J9FA13000012 | M32: もち | N32: J9F | O32: A | P32: 農産食品 | Q32: 1 | R32: 3 | S32: 精米 | T32: 精米 | U32: 0 | V32: 0 | W32: 精米 | X32: 精米 | Y32: 0 | Z32: 0 | AA32: 精米 | AB32: 精米 | AC32: 1 | AD32: 2 | AE32: もち | AF32: もち | AJ32: =IF(OR(AS32=1,AT32=1,AU32=1,AV32=1,AW32=1,AX32=1,AY32=1,AZ32=1,BA32=1,BB32=1,BC32=1,BD32=1),TRUE,FALSE) -> FALSE | AK32: =O32&Q32&R32&U32&V32&Y32&Z32&AC32&AD32 -> A13000012 | AL32: 72622 | AM32: =C32<>AK32 -> TRUE | AN32: =N32&AK32 -> J9FA13000012 | AR32: =IF(AL32<>"",1,"") -> 1 | AS32: =IF(IFERROR(VLOOKUP(AE32,#REF!,1,0),"")<>"",1,"") | AT32: =IF(IFERROR(VLOOKUP(AE32,#REF!,1,0),"")<>"",1,"") | AU32: =IF(IFERROR(VLOOKUP(AE32,#REF!,1,0),"")<>"",1,"") | AV32: =IF(IFERROR(VLOOKUP(AE32,#REF!,1,0),"")<>"",1,"") | AW32: =IF(IFERROR(VLOOKUP(AE32,#REF!,1,0),"")<>"",1,"") | AX32: =IF(IFERROR(VLOOKUP(AE32,#REF!,1,0),"")<>"",1,"") | AY32: =IF(IFERROR(VLOOKUP(AE32,#REF!,1,0),"")<>"",1,"") | AZ32: =IF(IFERROR(VLOOKUP(AE32,#REF!,1,0),"")<>"",1,"") | BA32: =IF(IFERROR(VLOOKUP(AE32,#REF!,1,0),"")<>"",1,"") | BB32: =IF(IFERROR(VLOOKUP(AE32,#REF!,1,0),"")<>"",1,"") | BC32: =IF(IFERROR(VLOOKUP(AE32,#REF!,1,0),"")<>"",1,"") | BD32: =IF(IFERROR(VLOOKUP(AE32,#REF!,1,0),"")<>"",1,"") | BE32: =SUM(AR32:BD32) -> 1
A33: 170 | B33: 6951 | C33: =LEFT(B33 & "000000000", 9) -> 695100000 | D33: =MID(C33,1,2) -> 69 | E33: =MID(C33,3,1) -> 5 | F33: =MID(C33,4,1) -> 1 | G33: =MID(C33,5,1) -> 0 | H33: =MID(C33,6,1) -> 0 | I33: =MID(C33,7,1) -> 0 | J33: =MID(C33,8,1) -> 0 | K33: =MID(C33,9,1) -> 0 | L33: J9FA13000013 | M33: 米粉（白玉粉及びみじん粉を含む。） | N33: J9F | O33: A | P33: 農産食品 | Q33: 1 | R33: 3 | S33: 精米 | T33: 精米 | U33: 0 | V33: 0 | W33: 精米 | X33: 精米 | Y33: 0 | Z33: 0 | AA33: 精米 | AB33: 精米 | AC33: 1 | AD33: 3 | AE33: 米粉（白玉粉及びみじん粉を含む。） | AF33: 米粉 | AJ33: =IF(OR(AS33=1,AT33=1,AU33=1,AV33=1,AW33=1,AX33=1,AY33=1,AZ33=1,BA33=1,BB33=1,BC33=1,BD33=1),TRUE,FALSE) -> FALSE | AK33: =O33&Q33&R33&U33&V33&Y33&Z33&AC33&AD33 -> A13000013 | AL33: 6951 | AM33: =C33<>AK33 -> TRUE | AN33: =N33&AK33 -> J9FA13000013 | AO33: こめ粉、寒梅粉、みじん粉、白玉粉、上新粉、もち米粉 | AR33: =IF(AL33<>"",1,"") -> 1 | AS33: =IF(IFERROR(VLOOKUP(AE33,#REF!,1,0),"")<>"",1,"") | AT33: =IF(IFERROR(VLOOKUP(AE33,#REF!,1,0),"")<>"",1,"") | AU33: =IF(IFERROR(VLOOKUP(AE33,#REF!,1,0),"")<>"",1,"") | AV33: =IF(IFERROR(VLOOKUP(AE33,#REF!,1,0),"")<>"",1,"") | AW33: =IF(IFERROR(VLOOKUP(AE33,#REF!,1,0),"")<>"",1,"") | AX33: =IF(IFERROR(VLOOKUP(AE33,#REF!,1,0),"")<>"",1,"") | AY33: =IF(IFERROR(VLOOKUP(AE33,#REF!,1,0),"")<>"",1,"") | AZ33: =IF(IFERROR(VLOOKUP(AE33,#REF!,1,0),"")<>"",1,"") | BA33: =IF(IFERROR(VLOOKUP(AE33,#REF!,1,0),"")<>"",1,"") | BB33: =IF(IFERROR(VLOOKUP(AE33,#REF!,1,0),"")<>"",1,"") | BC33: =IF(IFERROR(VLOOKUP(AE33,#REF!,1,0),"")<>"",1,"") | BD33: =IF(IFERROR(VLOOKUP(AE33,#REF!,1,0),"")<>"",1,"") | BE33: =SUM(AR33:BD33) -> 1
A34: 171 | B34: 69511 | C34: =LEFT(B34 & "000000000", 9) -> 695110000 | D34: =MID(C34,1,2) -> 69 | E34: =MID(C34,3,1) -> 5 | F34: =MID(C34,4,1) -> 1 | G34: =MID(C34,5,1) -> 1 | H34: =MID(C34,6,1) -> 0 | I34: =MID(C34,7,1) -> 0 | J34: =MID(C34,8,1) -> 0 | K34: =MID(C34,9,1) -> 0 | L34: J9FA13000014 | M34: うるち米粉 | N34: J9F | O34: A | P34: 農産食品 | Q34: 1 | R34: 3 | S34: 精米 | T34: 精米 | U34: 0 | V34: 0 | W34: 精米 | X34: 精米 | Y34: 0 | Z34: 0 | AA34: 精米 | AB34: 精米 | AC34: 1 | AD34: 4 | AE34: うるち米粉 | AF34: うるち米粉 | AH34: 1 | AJ34: =IF(OR(AS34=1,AT34=1,AU34=1,AV34=1,AW34=1,AX34=1,AY34=1,AZ34=1,BA34=1,BB34=1,BC34=1,BD34=1),TRUE,FALSE) -> FALSE | AK34: =O34&Q34&R34&U34&V34&Y34&Z34&AC34&AD34 -> A13000014 | AL34: 69511 | AM34: =C34<>AK34 -> TRUE | AN34: =N34&AK34 -> J9FA13000014 | AR34: =IF(AL34<>"",1,"") -> 1 | AS34: =IF(IFERROR(VLOOKUP(AE34,#REF!,1,0),"")<>"",1,"") | AT34: =IF(IFERROR(VLOOKUP(AE34,#REF!,1,0),"")<>"",1,"") | AU34: =IF(IFERROR(VLOOKUP(AE34,#REF!,1,0),"")<>"",1,"") | AV34: =IF(IFERROR(VLOOKUP(AE34,#REF!,1,0),"")<>"",1,"") | AW34: =IF(IFERROR(VLOOKUP(AE34,#REF!,1,0),"")<>"",1,"") | AX34: =IF(IFERROR(VLOOKUP(AE34,#REF!,1,0),"")<>"",1,"") | AY34: =IF(IFERROR(VLOOKUP(AE34,#REF!,1,0),"")<>"",1,"") | AZ34: =IF(IFERROR(VLOOKUP(AE34,#REF!,1,0),"")<>"",1,"") | BA34: =IF(IFERROR(VLOOKUP(AE34,#REF!,1,0),"")<>"",1,"") | BB34: =IF(IFERROR(VLOOKUP(AE34,#REF!,1,0),"")<>"",1,"") | BC34: =IF(IFERROR(VLOOKUP(AE34,#REF!,1,0),"")<>"",1,"") | BD34: =IF(IFERROR(VLOOKUP(AE34,#REF!,1,0),"")<>"",1,"") | BE34: =SUM(AR34:BD34) -> 1
A35: 172 | B35: 695111 | C35: =LEFT(B35 & "000000000", 9) -> 695111000 | D35: =MID(C35,1,2) -> 69 | E35: =MID(C35,3,1) -> 5 | F35: =MID(C35,4,1) -> 1 | G35: =MID(C35,5,1) -> 1 | H35: =MID(C35,6,1) -> 1 | I35: =MID(C35,7,1) -> 0 | J35: =MID(C35,8,1) -> 0 | K35: =MID(C35,9,1) -> 0 | L35: J9FA13000015 | M35: 上新粉 | N35: J9F | O35: A | P35: 農産食品 | Q35: 1 | R35: 3 | S35: 精米 | T35: 精米 | U35: 0 | V35: 0 | W35: 精米 | X35: 精米 | Y35: 0 | Z35: 0 | AA35: 精米 | AB35: 精米 | AC35: 1 | AD35: 5 | AE35: 上新粉 | AF35: 上新粉 | AH35: 1 | AI35: 米粉の同義語に移動 | AJ35: =IF(OR(AS35=1,AT35=1,AU35=1,AV35=1,AW35=1,AX35=1,AY35=1,AZ35=1,BA35=1,BB35=1,BC35=1,BD35=1),TRUE,FALSE) -> FALSE | AK35: =O35&Q35&R35&U35&V35&Y35&Z35&AC35&AD35 -> A13000015 | AL35: 695111 | AM35: =C35<>AK35 -> TRUE | AN35: =N35&AK35 -> J9FA13000015 | AR35: =IF(AL35<>"",1,"") -> 1 | AS35: =IF(IFERROR(VLOOKUP(AE35,#REF!,1,0),"")<>"",1,"") | AT35: =IF(IFERROR(VLOOKUP(AE35,#REF!,1,0),"")<>"",1,"") | AU35: =IF(IFERROR(VLOOKUP(AE35,#REF!,1,0),"")<>"",1,"") | AV35: =IF(IFERROR(VLOOKUP(AE35,#REF!,1,0),"")<>"",1,"") | AW35: =IF(IFERROR(VLOOKUP(AE35,#REF!,1,0),"")<>"",1,"") | AX35: =IF(IFERROR(VLOOKUP(AE35,#REF!,1,0),"")<>"",1,"") | AY35: =IF(IFERROR(VLOOKUP(AE35,#REF!,1,0),"")<>"",1,"") | AZ35: =IF(IFERROR(VLOOKUP(AE35,#REF!,1,0),"")<>"",1,"") | BA35: =IF(IFERROR(VLOOKUP(AE35,#REF!,1,0),"")<>"",1,"") | BB35: =IF(IFERROR(VLOOKUP(AE35,#REF!,1,0),"")<>"",1,"") | BC35: =IF(IFERROR(VLOOKUP(AE35,#REF!,1,0),"")<>"",1,"") | BD35: =IF(IFERROR(VLOOKUP(AE35,#REF!,1,0),"")<>"",1,"") | BE35: =SUM(AR35:BD35) -> 1
A36: 173 | B36: 695119 | C36: =LEFT(B36 & "000000000", 9) -> 695119000 | D36: =MID(C36,1,2) -> 69 | E36: =MID(C36,3,1) -> 5 | F36: =MID(C36,4,1) -> 1 | G36: =MID(C36,5,1) -> 1 | H36: =MID(C36,6,1) -> 9 | I36: =MID(C36,7,1) -> 0 | J36: =MID(C36,8,1) -> 0 | K36: =MID(C36,9,1) -> 0 | M36: その他のうるち米粉 | O36: A | P36: 農産食品 | Q36: 1 | S36: 精米 | T36: 精米 | U36: 0 | V36: 0 | X36: 精米 | Y36: 0 | Z36: 0 | AB36: 精米 | AC36: 0 | AD36: 0 | AE36: その他のうるち米粉 | AG36: 1 | AH36: 1 | AK36: =O36&Q36&#REF!&U36&V36&Y36&Z36&AC36&AD36 -> #REF! | AL36: 695119 | AM36: =C36<>AK36 -> #REF! | AR36: =IF(AL36<>"",1,"") -> 1 | AS36: =IF(IFERROR(VLOOKUP(AE36,#REF!,1,0),"")<>"",1,"") | AT36: =IF(IFERROR(VLOOKUP(AE36,#REF!,1,0),"")<>"",1,"") | AU36: =IF(IFERROR(VLOOKUP(AE36,#REF!,1,0),"")<>"",1,"") | AV36: =IF(IFERROR(VLOOKUP(AE36,#REF!,1,0),"")<>"",1,"") | AW36: =IF(IFERROR(VLOOKUP(AE36,#REF!,1,0),"")<>"",1,"") | AX36: =IF(IFERROR(VLOOKUP(AE36,#REF!,1,0),"")<>"",1,"") | AY36: =IF(IFERROR(VLOOKUP(AE36,#REF!,1,0),"")<>"",1,"") | AZ36: =IF(IFERROR(VLOOKUP(AE36,#REF!,1,0),"")<>"",1,"") | BA36: =IF(IFERROR(VLOOKUP(AE36,#REF!,1,0),"")<>"",1,"") | BB36: =IF(IFERROR(VLOOKUP(AE36,#REF!,1,0),"")<>"",1,"") | BC36: =IF(IFERROR(VLOOKUP(AE36,#REF!,1,0),"")<>"",1,"") | BD36: =IF(IFERROR(VLOOKUP(AE36,#REF!,1,0),"")<>"",1,"") | BE36: =SUM(AR36:BD36) -> 1
A37: 174 | B37: 69512 | C37: =LEFT(B37 & "000000000", 9) -> 695120000 | D37: =MID(C37,1,2) -> 69 | E37: =MID(C37,3,1) -> 5 | F37: =MID(C37,4,1) -> 1 | G37: =MID(C37,5,1) -> 2 | H37: =MID(C37,6,1) -> 0 | I37: =MID(C37,7,1) -> 0 | J37: =MID(C37,8,1) -> 0 | K37: =MID(C37,9,1) -> 0 | L37: J9FA13000016 | M37: もち米粉 | N37: J9F | O37: A | P37: 農産食品 | Q37: 1 | R37: 3 | S37: 精米 | T37: 精米 | U37: 0 | V37: 0 | W37: 精米 | X37: 精米 | Y37: 0 | Z37: 0 | AA37: 精米 | AB37: 精米 | AC37: 1 | AD37: 6 | AE37: もち米粉 | AF37: もち米粉 | AH37: 1 | AI37: 米粉の同義語に移動 | AJ37: =IF(OR(AS37=1,AT37=1,AU37=1,AV37=1,AW37=1,AX37=1,AY37=1,AZ37=1,BA37=1,BB37=1,BC37=1,BD37=1),TRUE,FALSE) -> FALSE | AK37: =O37&Q37&R37&U37&V37&Y37&Z37&AC37&AD37 -> A13000016 | AL37: 69512 | AM37: =C37<>AK37 -> TRUE | AN37: =N37&AK37 -> J9FA13000016 | AR37: =IF(AL37<>"",1,"") -> 1 | AS37: =IF(IFERROR(VLOOKUP(AE37,#REF!,1,0),"")<>"",1,"") | AT37: =IF(IFERROR(VLOOKUP(AE37,#REF!,1,0),"")<>"",1,"") | AU37: =IF(IFERROR(VLOOKUP(AE37,#REF!,1,0),"")<>"",1,"") | AV37: =IF(IFERROR(VLOOKUP(AE37,#REF!,1,0),"")<>"",1,"") | AW37: =IF(IFERROR(VLOOKUP(AE37,#REF!,1,0),"")<>"",1,"") | AX37: =IF(IFERROR(VLOOKUP(AE37,#REF!,1,0),"")<>"",1,"") | AY37: =IF(IFERROR(VLOOKUP(AE37,#REF!,1,0),"")<>"",1,"") | AZ37: =IF(IFERROR(VLOOKUP(AE37,#REF!,1,0),"")<>"",1,"") | BA37: =IF(IFERROR(VLOOKUP(AE37,#REF!,1,0),"")<>"",1,"") | BB37: =IF(IFERROR(VLOOKUP(AE37,#REF!,1,0),"")<>"",1,"") | BC37: =IF(IFERROR(VLOOKUP(AE37,#REF!,1,0),"")<>"",1,"") | BD37: =IF(IFERROR(VLOOKUP(AE37,#REF!,1,0),"")<>"",1,"") | BE37: =SUM(AR37:BD37) -> 1
A38: 175 | B38: 695121 | C38: =LEFT(B38 & "000000000", 9) -> 695121000 | D38: =MID(C38,1,2) -> 69 | E38: =MID(C38,3,1) -> 5 | F38: =MID(C38,4,1) -> 1 | G38: =MID(C38,5,1) -> 2 | H38: =MID(C38,6,1) -> 1 | I38: =MID(C38,7,1) -> 0 | J38: =MID(C38,8,1) -> 0 | K38: =MID(C38,9,1) -> 0 | L38: J9FA13000017 | M38: 白玉粉 | N38: J9F | O38: A | P38: 農産食品 | Q38: 1 | R38: 3 | S38: 精米 | T38: 精米 | U38: 0 | V38: 0 | W38: 精米 | X38: 精米 | Y38: 0 | Z38: 0 | AA38: 精米 | AB38: 精米 | AC38: 1 | AD38: 7 | AE38: 白玉粉 | AF38: 白玉粉 | AH38: 1 | AI38: 米粉の同義語に移動 | AJ38: =IF(OR(AS38=1,AT38=1,AU38=1,AV38=1,AW38=1,AX38=1,AY38=1,AZ38=1,BA38=1,BB38=1,BC38=1,BD38=1),TRUE,FALSE) -> FALSE | AK38: =O38&Q38&R38&U38&V38&Y38&Z38&AC38&AD38 -> A13000017 | AL38: 695121 | AM38: =C38<>AK38 -> TRUE | AN38: =N38&AK38 -> J9FA13000017 | AR38: =IF(AL38<>"",1,"") -> 1 | AS38: =IF(IFERROR(VLOOKUP(AE38,#REF!,1,0),"")<>"",1,"") | AT38: =IF(IFERROR(VLOOKUP(AE38,#REF!,1,0),"")<>"",1,"") | AU38: =IF(IFERROR(VLOOKUP(AE38,#REF!,1,0),"")<>"",1,"") | AV38: =IF(IFERROR(VLOOKUP(AE38,#REF!,1,0),"")<>"",1,"") | AW38: =IF(IFERROR(VLOOKUP(AE38,#REF!,1,0),"")<>"",1,"") | AX38: =IF(IFERROR(VLOOKUP(AE38,#REF!,1,0),"")<>"",1,"") | AY38: =IF(IFERROR(VLOOKUP(AE38,#REF!,1,0),"")<>"",1,"") | AZ38: =IF(IFERROR(VLOOKUP(AE38,#REF!,1,0),"")<>"",1,"") | BA38: =IF(IFERROR(VLOOKUP(AE38,#REF!,1,0),"")<>"",1,"") | BB38: =IF(IFERROR(VLOOKUP(AE38,#REF!,1,0),"")<>"",1,"") | BC38: =IF(IFERROR(VLOOKUP(AE38,#REF!,1,0),"")<>"",1,"") | BD38: =IF(IFERROR(VLOOKUP(AE38,#REF!,1,0),"")<>"",1,"") | BE38: =SUM(AR38:BD38) -> 1
A39: 176 | B39: 695122 | C39: =LEFT(B39 & "000000000", 9) -> 695122000 | D39: =MID(C39,1,2) -> 69 | E39: =MID(C39,3,1) -> 5 | F39: =MID(C39,4,1) -> 1 | G39: =MID(C39,5,1) -> 2 | H39: =MID(C39,6,1) -> 2 | I39: =MID(C39,7,1) -> 0 | J39: =MID(C39,8,1) -> 0 | K39: =MID(C39,9,1) -> 0 | L39: J9FA13000018 | M39: もち粉 | N39: J9F | O39: A | P39: 農産食品 | Q39: 1 | R39: 3 | S39: 精米 | T39: 精米 | U39: 0 | V39: 0 | W39: 精米 | X39: 精米 | Y39: 0 | Z39: 0 | AA39: 精米 | AB39: 精米 | AC39: 1 | AD39: 8 | AE39: もち粉 | AF39: もち粉 | AH39: 1 | AI39: 米粉の同義語に移動 | AJ39: =IF(OR(AS39=1,AT39=1,AU39=1,AV39=1,AW39=1,AX39=1,AY39=1,AZ39=1,BA39=1,BB39=1,BC39=1,BD39=1),TRUE,FALSE) -> FALSE | AK39: =O39&Q39&R39&U39&V39&Y39&Z39&AC39&AD39 -> A13000018 | AL39: 695122 | AM39: =C39<>AK39 -> TRUE | AN39: =N39&AK39 -> J9FA13000018 | AR39: =IF(AL39<>"",1,"") -> 1 | AS39: =IF(IFERROR(VLOOKUP(AE39,#REF!,1,0),"")<>"",1,"") | AT39: =IF(IFERROR(VLOOKUP(AE39,#REF!,1,0),"")<>"",1,"") | AU39: =IF(IFERROR(VLOOKUP(AE39,#REF!,1,0),"")<>"",1,"") | AV39: =IF(IFERROR(VLOOKUP(AE39,#REF!,1,0),"")<>"",1,"") | AW39: =IF(IFERROR(VLOOKUP(AE39,#REF!,1,0),"")<>"",1,"") | AX39: =IF(IFERROR(VLOOKUP(AE39,#REF!,1,0),"")<>"",1,"") | AY39: =IF(IFERROR(VLOOKUP(AE39,#REF!,1,0),"")<>"",1,"") | AZ39: =IF(IFERROR(VLOOKUP(AE39,#REF!,1,0),"")<>"",1,"") | BA39: =IF(IFERROR(VLOOKUP(AE39,#REF!,1,0),"")<>"",1,"") | BB39: =IF(IFERROR(VLOOKUP(AE39,#REF!,1,0),"")<>"",1,"") | BC39: =IF(IFERROR(VLOOKUP(AE39,#REF!,1,0),"")<>"",1,"") | BD39: =IF(IFERROR(VLOOKUP(AE39,#REF!,1,0),"")<>"",1,"") | BE39: =SUM(AR39:BD39) -> 1
A40: 177 | B40: 695123 | C40: =LEFT(B40 & "000000000", 9) -> 695123000 | D40: =MID(C40,1,2) -> 69 | E40: =MID(C40,3,1) -> 5 | F40: =MID(C40,4,1) -> 1 | G40: =MID(C40,5,1) -> 2 | H40: =MID(C40,6,1) -> 3 | I40: =MID(C40,7,1) -> 0 | J40: =MID(C40,8,1) -> 0 | K40: =MID(C40,9,1) -> 0 | L40: J9FA13000019 | M40: 寒梅粉 | N40: J9F | O40: A | P40: 農産食品 | Q40: 1 | R40: 3 | S40: 精米 | T40: 精米 | U40: 0 | V40: 0 | W40: 精米 | X40: 精米 | Y40: 0 | Z40: 0 | AA40: 精米 | AB40: 精米 | AC40: 1 | AD40: 9 | AE40: 寒梅粉 | AF40: 寒梅粉 | AH40: 1 | AI40: 米粉の同義語に移動 | AJ40: =IF(OR(AS40=1,AT40=1,AU40=1,AV40=1,AW40=1,AX40=1,AY40=1,AZ40=1,BA40=1,BB40=1,BC40=1,BD40=1),TRUE,FALSE) -> FALSE | AK40: =O40&Q40&R40&U40&V40&Y40&Z40&AC40&AD40 -> A13000019 | AL40: 695123 | AM40: =C40<>AK40 -> TRUE | AN40: =N40&AK40 -> J9FA13000019 | AR40: =IF(AL40<>"",1,"") -> 1 | AS40: =IF(IFERROR(VLOOKUP(AE40,#REF!,1,0),"")<>"",1,"") | AT40: =IF(IFERROR(VLOOKUP(AE40,#REF!,1,0),"")<>"",1,"") | AU40: =IF(IFERROR(VLOOKUP(AE40,#REF!,1,0),"")<>"",1,"") | AV40: =IF(IFERROR(VLOOKUP(AE40,#REF!,1,0),"")<>"",1,"") | AW40: =IF(IFERROR(VLOOKUP(AE40,#REF!,1,0),"")<>"",1,"") | AX40: =IF(IFERROR(VLOOKUP(AE40,#REF!,1,0),"")<>"",1,"") | AY40: =IF(IFERROR(VLOOKUP(AE40,#REF!,1,0),"")<>"",1,"") | AZ40: =IF(IFERROR(VLOOKUP(AE40,#REF!,1,0),"")<>"",1,"") | BA40: =IF(IFERROR(VLOOKUP(AE40,#REF!,1,0),"")<>"",1,"") | BB40: =IF(IFERROR(VLOOKUP(AE40,#REF!,1,0),"")<>"",1,"") | BC40: =IF(IFERROR(VLOOKUP(AE40,#REF!,1,0),"")<>"",1,"") | BD40: =IF(IFERROR(VLOOKUP(AE40,#REF!,1,0),"")<>"",1,"") | BE40: =SUM(AR40:BD40) -> 1
...

Sheet ★ JPFHIRアレルゲンコード設計
B1: ★ JFAGYアレルゲンコード設計
C3: 番号の意味 | D3: 値の定義 | E3: JFAGY（食品） | F3: JFAGY（非食品） | G3: YJ12桁 | H3: YJ9桁（厚労省一般名処方マスタ） | I3: WHO-ATC分類
A4: 1 | B4: メタコード領域 | C4: コアコード識別記号 | D4: J：JFAGY、Y：YJコード、A：ATC分類 | E4: J | F4: J | G4: Y | H4: Y | I4: A
A5: 2 | C5: コアコードのコード長 | D5: 0〜9、A〜Z（36進数） | E5: 9 | F5: 9 | G5: C | H5: 9 | I5: 7
A6: 3 | C6: コアコードが対象とするアレルゲン領域 | D6: F：食品・飲料、M：医薬品、N：非食品・非医薬品 | E6: F | F6: N | G6: M | H6: M | I6: M
A7: 4 | B7: コアコード領域 | E7: 第1コード 1桁 | F7: 第1コード 1桁 | G7: 薬効分類コード（日本商品分類コード4桁） | H7: 薬効分類コード（日本商品分類コード4桁） | I7: レベル1：解剖学的部位メイングループ
A8: 5 | E8: 第2コードと第3コードがセット（２桁） | F8: 第2コードと第3コードがセット（２桁） | I8: レベル2：治療法サブグループ
A9: 6
A10: 7 | E10: 第4コードと第5コードがセット（２桁） | F10: 第4コードと第5コードがセット（２桁） | I10: レベル3：薬理学サブグループ
A11: 8 | G11: 投与経路・成分分類番号 | H11: 投与経路・成分分類番号 | I11: レベル4：化学サブグループ
A12: 9 | E12: 第6コードと第7コードがセット（２桁） | F12: 第6コードと第7コードがセット（２桁） | I12: レベル5：化学物質
A13: 10
A14: 11 | E14: 枝番1 | F14: 枝番1 | G14: 剤形 | H14: 剤形
A15: 12 | E15: 枝番2 | F15: 枝番2 | G15: 規格単位別番号 | H15: 規格単位別番号
A16: 13 | G16: 同一規格内順序番号 | H16: Z
A17: 14 | H17: Z
A18: 15 | G18: YJチェックディジット | H18: Z
G19: 製造会社の別を問いたい場合 | H19: 製造会社は気にしない（「一般的名称」＋「剤形」＋「含量」）
G20: ロサルタンカリウム錠２５ｍｇ「アメル」 | 2149039F1244 | H20: ロサルタンカリウム錠２５ｍｇ | 2149039F1 | K20: 一般名コード
G21: ロサルタンカリウム錠２５ｍｇ「NP」 | 2149039F1201 | K21: https://www.mhlw.go.jp/seisakunitsuite/bunya/kenkou_iryou/iryouhoken/shohosen_200401.html
G22: ロサルタンカリウム錠２５ｍｇ「サンド」 | 2149039F1287
K24: 一般用医薬品コード（経済課コード）
K25: https://www.japic.or.jp/service/whats_new/otc_codes/index.php

Sheet ☆JFAGY_V8件数集計☆
B1: 2022/10/21作成
B3: JFAGY（食品・非食品ICD11）V8シート
C4: 件数（削除フラグは除いています）
B5: J-FAGY(不要フラグを付ける前) | C5: =COUNTIF('JFAGY（食品・非食品ICD11）V8'!AG2:AG3600,"") -> 3074 | D5: ←削除フラグ有りを除いた件数
B6: 不要フラグ付与 | C6: =COUNTIFS('JFAGY（食品・非食品ICD11）V8'!AG:AG,"",'JFAGY（食品・非食品ICD11）V8'!AH:AH,"1") -> 1266 | D6: ←削除フラグ：なし、不要フラグ：有りの件数
B7: J-FAGY(不要フラグの除いた件数) | C7: =C5-C6 -> 1808 | D7: ←現在の最終J-FAGY件数 | F7: =COUNTIFS('JFAGY（食品・非食品ICD11）V8'!AG:AG,"",'JFAGY（食品・非食品ICD11）V8'!AH:AH,"") -> 1046784 | G7: ←削除フラグ：なし、不要フラグ：なし の件数
C9: 件数（削除フラグは除いています）
B10: 食品 | C10: =COUNTIFS('JFAGY（食品・非食品ICD11）V8'!AG:AG,"",'JFAGY（食品・非食品ICD11）V8'!AH:AH,"",'JFAGY（食品・非食品ICD11）V8'!N:N,"J9F") -> 1182 | D10: ←現在のJ-FAGY 食品用語件数
B11: 非食品 | C11: =COUNTIFS('JFAGY（食品・非食品ICD11）V8'!AG:AG,"",'JFAGY（食品・非食品ICD11）V8'!AH:AH,"",'JFAGY（食品・非食品ICD11）V8'!N:N,"J9N") -> 626 | D11: ←現在のJ-FAGY 非食品用語件数
B12: 合計 | C12: =SUM(C10:C11) -> 1808 | D12: ←現在の最終J-FAGY件数
C14: 件数（削除フラグは除いています）
B15: J-FAGY(不要フラグの除いた件数)のうち、アレルギーガイドラインにはないもの | C15: =COUNTIFS('JFAGY（食品・非食品ICD11）V8'!AJ:AJ,"FALSE",'JFAGY（食品・非食品ICD11）V8'!AG:AG,"",'JFAGY（食品・非食品ICD11）V8'!AH:AH,"") -> 1808 | D15: ※この用語の再検討が必要（さらに不要と判断できるものはないか？）例 赤いんげん、青いんげん
B16: J-FAGY(不要フラグの除いた件数)のうち、アレルギーガイドラインに有るもの | C16: =COUNTIFS('JFAGY（食品・非食品ICD11）V8'!AJ:AJ,"TRUE",'JFAGY（食品・非食品ICD11）V8'!AG:AG,"",'JFAGY（食品・非食品ICD11）V8'!AH:AH,"") -> 0
B17: 合計 | C17: =SUM(C15:C16) -> 1808 | D17: ←現在の最終J-FAGY件数と一致するはず
B20: ソート後のＶ８行数 | C20: =SUBTOTAL(3,'JFAGY（食品・非食品ICD11）V8'!AE2:AE3600) -> 3599 | D20: ←現在表示されている件数
